Workbook
Name \0: [1]DIRIND!$U$1
Name \a: #N/A
Name RECADM: #N/A

Sheet byGOVDetalhado
A1: Arrecadação Direta por Esfera de Governo
A3: Esfera de Governo | B3: 2000 | F3: 2001 | J3: 2002 | N3: 2003 | R3: 2004 | V3: 2005 | Z3: 2006 | AD3: 2007 | AH3: 2008 | AL3: 2009 | AP3: 2010 | AT3: 2011 | AX3: 2012 | BB3: 2013 | BF3: 2014 | BJ3: 2015 | BN3: 2016 | BR3: 2017 | BV3: 2018 | BZ3: 2019 | CD3: 2020 | CH3: 2021 | CL3: 2022 | CP3: 2023 | CT3: 2024
B4: R$ Bilhões | C4: % PIB | D4: % Total | E4: Per capita (R$) | F4: R$ Bilhões | G4: % PIB | H4: % Total | I4: Per capita (R$) | J4: R$ Bilhões | K4: % PIB | L4: % Total | M4: Per capita (R$) | N4: R$ Bilhões | O4: % PIB | P4: % Total | Q4: Per capita (R$) | R4: R$ Bilhões | S4: % PIB | T4: % Total | U4: Per capita (R$) | V4: R$ Bilhões | W4: % PIB | X4: % Total | Y4: Per capita (R$) | Z4: R$ Bilhões | AA4: % PIB | AB4: % Total | AC4: Per capita (R$) | AD4: R$ Bilhões | AE4: % PIB | AF4: % Total | AG4: Per capita (R$) | AH4: R$ Bilhões | AI4: % PIB | AJ4: % Total | AK4: Per capita (R$) | AL4: R$ Bilhões | AM4: % PIB | AN4: % Total | AO4: Per capita (R$) | AP4: R$ Bilhões | AQ4: % PIB | AR4: % Total | AS4: Per capita (R$) | AT4: R$ Bilhões | AU4: % PIB | AV4: % Total | AW4: Per capita (R$) | AX4: R$ Bilhões | AY4: % PIB | AZ4: % Total | BA4: Per capita (R$) | BB4: R$ Bilhões | BC4: % PIB | BD4: % Total | BE4: Per capita (R$) | BF4: R$ Bilhões | BG4: % PIB | BH4: % Total | BI4: Per capita (R$) | BJ4: R$ Bilhões | BK4: % PIB | BL4: % Total | BM4: Per capita (R$) | BN4: R$ Bilhões | BO4: % PIB | BP4: % Total | BQ4: Per capita (R$) | BR4: R$ Bilhões | BS4: % PIB | BT4: % Total | BU4: Per capita (R$) | BV4: R$ Bilhões | BW4: % PIB | BX4: % Total | BY4: Per capita (R$) | BZ4: R$ Bilhões | CA4: % PIB | CB4: % Total | CC4: Per capita (R$) | CD4: R$ Bilhões | CE4: % PIB | CF4: % Total | CG4: Per capita (R$) | CH4: R$ Bilhões | CI4: % PIB | CJ4: % Total | CK4: Per capita (R$) | CL4: R$ Bilhões | CM4: % PIB | CN4: % Total | CO4: Per capita (R$) | CP4: R$ Bilhões | CQ4: % PIB | CR4: % Total | CS4: Per capita (R$) | CT4: R$ Bilhões | CU4: % PIB | CV4: % Total | CW4: Per capita (R$)
A5: PIB | B5: =[2]byGOVDetalhado!B5 -> 1202.3772 | C5: =[2]byGOVDetalhado!C5 -> 0 | D5: =[2]byGOVDetalhado!D5 -> 0 | E5: =[2]byGOVDetalhado!E5 -> 0 | F5: =[3]byGOVDetalhado!B5 -> 1315.755 | G5: =[3]byGOVDetalhado!C5 -> 0 | H5: =[3]byGOVDetalhado!D5 -> 0 | I5: =[3]byGOVDetalhado!E5 -> 0 | J5: =[4]byGOVDetalhado!B5 -> 1488.787 | K5: =[4]byGOVDetalhado!C5 -> 0 | L5: =[4]byGOVDetalhado!D5 -> 0 | M5: =[4]byGOVDetalhado!E5 -> 0 | N5: =[5]byGOVDetalhado!B5 -> 1717.95 | O5: =[5]byGOVDetalhado!C5 -> 0 | P5: =[5]byGOVDetalhado!D5 -> 0 | Q5: =[5]byGOVDetalhado!E5 -> 0 | R5: =[6]byGOVDetalhado!B5 -> 1957.751 | S5: =[6]byGOVDetalhado!C5 -> 0 | T5: =[6]byGOVDetalhado!D5 -> 0 | U5: =[6]byGOVDetalhado!E5 -> 0 | V5: =[7]byGOVDetalhado!B5 -> 2170.585 | W5: =[7]byGOVDetalhado!C5 -> 0 | X5: =[7]byGOVDetalhado!D5 -> 0 | Y5: =[7]byGOVDetalhado!E5 -> 0 | Z5: =[8]byGOVDetalhado!B5 -> 2409.45 | AA5: =[8]byGOVDetalhado!C5 -> 0 | AB5: =[8]byGOVDetalhado!D5 -> 0 | AC5: =[8]byGOVDetalhado!E5 -> 0 | AD5: =[9]byGOVDetalhado!B5 -> 2720.263 | AE5: =[9]byGOVDetalhado!C5 -> 0 | AF5: =[9]byGOVDetalhado!D5 -> 0 | AG5: =[9]byGOVDetalhado!E5 -> 0 | AH5: =[10]byGOVDetalhado!B5 -> 3109.803 | AI5: =[10]byGOVDetalhado!C5 -> 0 | AJ5: =[10]byGOVDetalhado!D5 -> 0 | AK5: =[10]byGOVDetalhado!E5 -> 0 | AL5: =[11]byGOVDetalhado!B5 -> 3333.039 | AM5: =[11]byGOVDetalhado!C5 -> 0 | AN5: =[11]byGOVDetalhado!D5 -> 0 | AO5: =[11]byGOVDetalhado!E5 -> 0 | AP5: =[12]byGOVDetalhado!B5 -> 3885.847 | AQ5: =[12]byGOVDetalhado!C5 -> 0 | AR5: =[12]byGOVDetalhado!D5 -> 0 | AS5: =[12]byGOVDetalhado!E5 -> 0 | AT5: =[13]byGOVDetalhado!B5 -> 4376.382 | AU5: =[13]byGOVDetalhado!C5 -> 0 | AV5: =[13]byGOVDetalhado!D5 -> 0 | AW5: =[13]byGOVDetalhado!E5 -> 0 | AX5: =[14]byGOVDetalhado!B5 -> 4814.76 | AY5: =[14]byGOVDetalhado!C5 -> 0 | AZ5: =[14]byGOVDetalhado!D5 -> 0 | BA5: =[14]byGOVDetalhado!E5 -> 0 | BB5: =[15]byGOVDetalhado!B5 -> 5331.619 | BC5: =[15]byGOVDetalhado!C5 -> 0 | BD5: =[15]byGOVDetalhado!D5 -> 0 | BE5: =[15]byGOVDetalhado!E5 -> 0 | BF5: =[16]byGOVDetalhado!B5 -> 5778.953 | BG5: =[16]byGOVDetalhado!C5 -> 0 | BH5: =[16]byGOVDetalhado!D5 -> 0 | BI5: =[16]byGOVDetalhado!E5 -> 0 | BJ5: =[17]byGOVDetalhado!B5 -> 5995.787 | BK5: =[17]byGOVDetalhado!C5 -> 0 | BL5: =[17]byGOVDetalhado!D5 -> 0 | BM5: =[17]byGOVDetalhado!E5 -> 0 | BN5: =[18]byGOVDetalhado!B5 -> 6267.205 | BO5: =[18]byGOVDetalhado!C5 -> 0 | BP5: =[18]byGOVDetalhado!D5 -> 0 | BQ5: =[18]byGOVDetalhado!E5 -> 0 | BR5: =[19]byGOVDetalhado!B5 -> 6553.8427 | BS5: =[19]byGOVDetalhado!C5 -> 0 | BT5: =[19]byGOVDetalhado!D5 -> 0 | BU5: =[19]byGOVDetalhado!E5 -> 0 | BV5: =[20]byGOVDetalhado!B5 -> 6889.1761 | BW5: =[20]byGOVDetalhado!C5 -> 0 | BX5: =[20]byGOVDetalhado!D5 -> 0 | BY5: =[20]byGOVDetalhado!E5 -> 0 | BZ5: =[21]byGOVDetalhado!B5 -> 7389.131 | CA5: =[21]byGOVDetalhado!C5 -> 0 | CB5: =[21]byGOVDetalhado!D5 -> 0 | CC5: =[21]byGOVDetalhado!E5 -> 0 | CD5: =[22]byGOVDetalhado!B5 -> 7609.597 | CE5: =[22]byGOVDetalhado!C5 -> 0 | CF5: =[22]byGOVDetalhado!D5 -> 0 | CG5: =[22]byGOVDetalhado!E5 -> 0 | CH5: =[23]byGOVDetalhado!B5 -> 8898.727 | CI5: =[23]byGOVDetalhado!C5 -> 0 | CJ5: =[23]byGOVDetalhado!D5 -> 0 | CK5: =[23]byGOVDetalhado!E5 -> 0 | CL5: =[24]byGOVDetalhado!B5 -> 10079.676 | CM5: =[24]byGOVDetalhado!C5 -> 0 | CN5: =[24]byGOVDetalhado!D5 -> 0 | CO5: =[24]byGOVDetalhado!E5 -> 0 | CP5: =[25]byGOVDetalhado!B5 -> 10943.344 | CQ5: =[25]byGOVDetalhado!C5 -> 0 | CR5: =[25]byGOVDetalhado!D5 -> 0 | CS5: =[25]byGOVDetalhado!E5 -> 0 | CT5: =[26]byGOVDetalhado!B5 -> 11744.709 | CU5: =[26]byGOVDetalhado!C5 -> 0 | CV5: =[26]byGOVDetalhado!D5 -> 0 | CW5: =[26]byGOVDetalhado!E5 -> 0
A6: População | B6: =[2]byGOVDetalhado!B6 -> 173448346 | C6: =[2]byGOVDetalhado!C6 -> 0 | D6: =[2]byGOVDetalhado!D6 -> 0 | E6: =[2]byGOVDetalhado!E6 -> 0 | F6: =[3]byGOVDetalhado!B6 -> 173448346 | G6: =[3]byGOVDetalhado!C6 -> 0 | H6: =[3]byGOVDetalhado!D6 -> 0 | I6: =[3]byGOVDetalhado!E6 -> 0 | J6: =[4]byGOVDetalhado!B6 -> 178276128 | K6: =[4]byGOVDetalhado!C6 -> 0 | L6: =[4]byGOVDetalhado!D6 -> 0 | M6: =[4]byGOVDetalhado!E6 -> 0 | N6: =[5]byGOVDetalhado!B6 -> 180619108 | O6: =[5]byGOVDetalhado!C6 -> 0 | P6: =[5]byGOVDetalhado!D6 -> 0 | Q6: =[5]byGOVDetalhado!E6 -> 0 | R6: =[6]byGOVDetalhado!B6 -> 182911487 | S6: =[6]byGOVDetalhado!C6 -> 0 | T6: =[6]byGOVDetalhado!D6 -> 0 | U6: =[6]byGOVDetalhado!E6 -> 0 | V6: =[7]byGOVDetalhado!B6 -> 185150806 | W6: =[7]byGOVDetalhado!C6 -> 0 | X6: =[7]byGOVDetalhado!D6 -> 0 | Y6: =[7]byGOVDetalhado!E6 -> 0 | Z6: =[8]byGOVDetalhado!B6 -> 187335137 | AA6: =[8]byGOVDetalhado!C6 -> 0 | AB6: =[8]byGOVDetalhado!D6 -> 0 | AC6: =[8]byGOVDetalhado!E6 -> 0 | AD6: =[9]byGOVDetalhado!B6 -> 189462755 | AE6: =[9]byGOVDetalhado!C6 -> 0 | AF6: =[9]byGOVDetalhado!D6 -> 0 | AG6: =[9]byGOVDetalhado!E6 -> 0 | AH6: =[10]byGOVDetalhado!B6 -> 191532439 | AI6: =[10]byGOVDetalhado!C6 -> 0 | AJ6: =[10]byGOVDetalhado!D6 -> 0 | AK6: =[10]byGOVDetalhado!E6 -> 0 | AL6: =[11]byGOVDetalhado!B6 -> 193543969 | AM6: =[11]byGOVDetalhado!C6 -> 0 | AN6: =[11]byGOVDetalhado!D6 -> 0 | AO6: =[11]byGOVDetalhado!E6 -> 0 | AP6: =[12]byGOVDetalhado!B6 -> 195497797 | AQ6: =[12]byGOVDetalhado!C6 -> 0 | AR6: =[12]byGOVDetalhado!D6 -> 0 | AS6: =[12]byGOVDetalhado!E6 -> 0 | AT6: =[13]byGOVDetalhado!B6 -> 197397018 | AU6: =[13]byGOVDetalhado!C6 -> 0 | AV6: =[13]byGOVDetalhado!D6 -> 0 | AW6: =[13]byGOVDetalhado!E6 -> 0 | AX6: =[14]byGOVDetalhado!B6 -> 199242462 | AY6: =[14]byGOVDetalhado!C6 -> 0 | AZ6: =[14]byGOVDetalhado!D6 -> 0 | BA6: =[14]byGOVDetalhado!E6 -> 0 | BB6: =[15]byGOVDetalhado!B6 -> 201032714 | BC6: =[15]byGOVDetalhado!C6 -> 0 | BD6: =[15]byGOVDetalhado!D6 -> 0 | BE6: =[15]byGOVDetalhado!E6 -> 0 | BF6: =[16]byGOVDetalhado!B6 -> 202768562 | BG6: =[16]byGOVDetalhado!C6 -> 0 | BH6: =[16]byGOVDetalhado!D6 -> 0 | BI6: =[16]byGOVDetalhado!E6 -> 0 | BJ6: =[17]byGOVDetalhado!B6 -> 204450649 | BK6: =[17]byGOVDetalhado!C6 -> 0 | BL6: =[17]byGOVDetalhado!D6 -> 0 | BM6: =[17]byGOVDetalhado!E6 -> 0 | BN6: =[18]byGOVDetalhado!B6 -> 206081432 | BO6: =[18]byGOVDetalhado!C6 -> 0 | BP6: =[18]byGOVDetalhado!D6 -> 0 | BQ6: =[18]byGOVDetalhado!E6 -> 0 | BR6: =[19]byGOVDetalhado!B6 -> 207660929 | BS6: =[19]byGOVDetalhado!C6 -> 0 | BT6: =[19]byGOVDetalhado!D6 -> 0 | BU6: =[19]byGOVDetalhado!E6 -> 0 | BV6: =[20]byGOVDetalhado!B6 -> 208494900 | BW6: =[20]byGOVDetalhado!C6 -> 0 | BX6: =[20]byGOVDetalhado!D6 -> 0 | BY6: =[20]byGOVDetalhado!E6 -> 0 | BZ6: =[21]byGOVDetalhado!B6 -> 210147125 | CA6: =[21]byGOVDetalhado!C6 -> 0 | CB6: =[21]byGOVDetalhado!D6 -> 0 | CC6: =[21]byGOVDetalhado!E6 -> 0 | CD6: =[22]byGOVDetalhado!B6 -> 211755692 | CE6: =[22]byGOVDetalhado!C6 -> 0 | CF6: =[22]byGOVDetalhado!D6 -> 0 | CG6: =[22]byGOVDetalhado!E6 -> 0 | CH6: =[23]byGOVDetalhado!B6 -> 213317639 | CI6: =[23]byGOVDetalhado!C6 -> 0 | CJ6: =[23]byGOVDetalhado!D6 -> 0 | CK6: =[23]byGOVDetalhado!E6 -> 0 | CL6: =[24]byGOVDetalhado!B6 -> 203080756 | CM6: =[24]byGOVDetalhado!C6 -> 0 | CN6: =[24]byGOVDetalhado!D6 -> 0 | CO6: =[24]byGOVDetalhado!E6 -> 0 | CP6: =[25]byGOVDetalhado!B6 -> 207832253 | CQ6: =[25]byGOVDetalhado!C6 -> 0 | CR6: =[25]byGOVDetalhado!D6 -> 0 | CS6: =[25]byGOVDetalhado!E6 -> 0 | CT6: =[26]byGOVDetalhado!B6 -> 212583750 | CU6: =[26]byGOVDetalhado!C6 -> 0 | CV6: =[26]byGOVDetalhado!D6 -> 0 | CW6: =[26]byGOVDetalhado!E6 -> 0
A7: TOTAL | B7: =[2]byGOVDetalhado!B7 -> 367.44515 | C7: =[2]byGOVDetalhado!C7 -> 30.559889 | D7: =[2]byGOVDetalhado!D7 -> 100 | E7: =[2]byGOVDetalhado!E7 -> 2118.4702 | F7: =[3]byGOVDetalhado!B7 -> 421.64663 | G7: =[3]byGOVDetalhado!C7 -> 32.045984 | H7: =[3]byGOVDetalhado!D7 -> 100 | I7: =[3]byGOVDetalhado!E7 -> 2430.9637 | J7: =[4]byGOVDetalhado!B7 -> 495.42481 | K7: =[4]byGOVDetalhado!C7 -> 33.277078 | L7: =[4]byGOVDetalhado!D7 -> 100 | M7: =[4]byGOVDetalhado!E7 -> 2778.9745 | N7: =[5]byGOVDetalhado!B7 -> 560.01487 | O7: =[5]byGOVDetalhado!C7 -> 32.597856 | P7: =[5]byGOVDetalhado!D7 -> 100 | Q7: =[5]byGOVDetalhado!E7 -> 3100.5295 | R7: =[6]byGOVDetalhado!B7 -> 658.25296 | S7: =[6]byGOVDetalhado!C7 -> 33.622915 | T7: =[6]byGOVDetalhado!D7 -> 100 | U7: =[6]byGOVDetalhado!E7 -> 3598.7513 | V7: =[7]byGOVDetalhado!B7 -> 754.18429 | W7: =[7]byGOVDetalhado!C7 -> 34.74567 | X7: =[7]byGOVDetalhado!D7 -> 100 | Y7: =[7]byGOVDetalhado!E7 -> 4073.3514 | Z7: =[8]byGOVDetalhado!B7 -> 829.53577 | AA7: =[8]byGOVDetalhado!C7 -> 34.428428 | AB7: =[8]byGOVDetalhado!D7 -> 100 | AC7: =[8]byGOVDetalhado!E7 -> 4428.0842 | AD7: =[9]byGOVDetalhado!B7 -> 940.81948 | AE7: =[9]byGOVDetalhado!C7 -> 34.585607 | AF7: =[9]byGOVDetalhado!D7 -> 100 | AG7: =[9]byGOVDetalhado!E7 -> 4965.7226 | AH7: =[10]byGOVDetalhado!B7 -> 1080.8859 | AI7: =[10]byGOVDetalhado!C7 -> 34.757375 | AJ7: =[10]byGOVDetalhado!D7 -> 100 | AK7: =[10]byGOVDetalhado!E7 -> 5643.3568 | AL7: =[11]byGOVDetalhado!B7 -> 1105.3741 | AM7: =[11]byGOVDetalhado!C7 -> 33.164151 | AN7: =[11]byGOVDetalhado!D7 -> 100 | AO7: =[11]byGOVDetalhado!E7 -> 5711.2298 | AP7: =[12]byGOVDetalhado!B7 -> 1291.3621 | AQ7: =[12]byGOVDetalhado!C7 -> 33.232448 | AR7: =[12]byGOVDetalhado!D7 -> 100 | AS7: =[12]byGOVDetalhado!E7 -> 6605.5071 | AT7: =[13]byGOVDetalhado!B7 -> 1491.6039 | AU7: =[13]byGOVDetalhado!C7 -> 34.083038 | AV7: =[13]byGOVDetalhado!D7 -> 100 | AW7: =[13]byGOVDetalhado!E7 -> 7556.3651 | AX7: =[14]byGOVDetalhado!B7 -> 1638.1111 | AY7: =[14]byGOVDetalhado!C7 -> 34.022696 | AZ7: =[14]byGOVDetalhado!D7 -> 100 | BA7: =[14]byGOVDetalhado!E7 -> 8221.6969 | BB7: =[15]byGOVDetalhado!B7 -> 1792.2461 | BC7: =[15]byGOVDetalhado!C7 -> 33.615419 | BD7: =[15]byGOVDetalhado!D7 -> 100 | BE7: =[15]byGOVDetalhado!E7 -> 8915.1961 | BF7: =[16]byGOVDetalhado!B7 -> 1899.7813 | BG7: =[16]byGOVDetalhado!C7 -> 32.874143 | BH7: =[16]byGOVDetalhado!D7 -> 100 | BI7: =[16]byGOVDetalhado!E7 -> 9369.2102 | BJ7: =[17]byGOVDetalhado!B7 -> 1969.031 | BK7: =[17]byGOVDetalhado!C7 -> 32.840243 | BL7: =[17]byGOVDetalhado!D7 -> 100 | BM7: =[17]byGOVDetalhado!E7 -> 9630.8376 | BN7: =[18]byGOVDetalhado!B7 -> 2086.1565 | BO7: =[18]byGOVDetalhado!C7 -> 33.286872 | BP7: =[18]byGOVDetalhado!D7 -> 100 | BQ7: =[18]byGOVDetalhado!E7 -> 10122.972 | BR7: =[19]byGOVDetalhado!B7 -> 2203.4045 | BS7: =[19]byGOVDetalhado!C7 -> 33.620039 | BT7: =[19]byGOVDetalhado!D7 -> 100 | BU7: =[19]byGOVDetalhado!E7 -> 10610.588 | BV7: =[20]byGOVDetalhado!B7 -> 2372.7995 | BW7: =[20]byGOVDetalhado!C7 -> 34.442428 | BX7: =[20]byGOVDetalhado!D7 -> 100 | BY7: =[20]byGOVDetalhado!E7 -> 11380.612 | BZ7: =[21]byGOVDetalhado!B7 -> 2496.9243 | CA7: =[21]byGOVDetalhado!C7 -> 33.791853 | CB7: =[21]byGOVDetalhado!D7 -> 100 | CC7: =[21]byGOVDetalhado!E7 -> 11881.791 | CD7: =[22]byGOVDetalhado!B7 -> 2451.5573 | CE7: =[22]byGOVDetalhado!C7 -> 32.216651 | CF7: =[22]byGOVDetalhado!D7 -> 100 | CG7: =[22]byGOVDetalhado!E7 -> 11577.291 | CH7: =[23]byGOVDetalhado!B7 -> 3060.9656 | CI7: =[23]byGOVDetalhado!C7 -> 34.397792 | CJ7: =[23]byGOVDetalhado!D7 -> 100 | CK7: =[23]byGOVDetalhado!E7 -> 14349.332 | CL7: =[24]byGOVDetalhado!B7 -> 3518.4966 | CM7: =[24]byGOVDetalhado!C7 -> 34.906843 | CN7: =[24]byGOVDetalhado!D7 -> 100 | CO7: =[24]byGOVDetalhado!E7 -> 17325.603 | CP7: =[25]byGOVDetalhado!B7 -> 3783.9875 | CQ7: =[25]byGOVDetalhado!C7 -> 34.577982 | CR7: =[25]byGOVDetalhado!D7 -> 100 | CS7: =[25]byGOVDetalhado!E7 -> 18206.931 | CT7: =[26]byGOVDetalhado!B7 -> 4222.222 | CU7: =[26]byGOVDetalhado!C7 -> 35.949992 | CV7: =[26]byGOVDetalhado!D7 -> 100 | CW7: =[26]byGOVDetalhado!E7 -> 19861.452
B8: =[2]byGOVDetalhado!B8 -> 0 | C8: =[2]byGOVDetalhado!C8 -> 0 | D8: =[2]byGOVDetalhado!D8 -> 0 | E8: =[2]byGOVDetalhado!E8 -> 0 | F8: =[3]byGOVDetalhado!B8 -> 0 | G8: =[3]byGOVDetalhado!C8 -> 0 | H8: =[3]byGOVDetalhado!D8 -> 0 | I8: =[3]byGOVDetalhado!E8 -> 0 | J8: =[4]byGOVDetalhado!B8 -> 0 | K8: =[4]byGOVDetalhado!C8 -> 0 | L8: =[4]byGOVDetalhado!D8 -> 0 | M8: =[4]byGOVDetalhado!E8 -> 0 | N8: =[5]byGOVDetalhado!B8 -> 0 | O8: =[5]byGOVDetalhado!C8 -> 0 | P8: =[5]byGOVDetalhado!D8 -> 0 | Q8: =[5]byGOVDetalhado!E8 -> 0 | R8: =[6]byGOVDetalhado!B8 -> 0 | S8: =[6]byGOVDetalhado!C8 -> 0 | T8: =[6]byGOVDetalhado!D8 -> 0 | U8: =[6]byGOVDetalhado!E8 -> 0 | V8: =[7]byGOVDetalhado!B8 -> 0 | W8: =[7]byGOVDetalhado!C8 -> 0 | X8: =[7]byGOVDetalhado!D8 -> 0 | Y8: =[7]byGOVDetalhado!E8 -> 0 | Z8: =[8]byGOVDetalhado!B8 -> 0 | AA8: =[8]byGOVDetalhado!C8 -> 0 | AB8: =[8]byGOVDetalhado!D8 -> 0 | AC8: =[8]byGOVDetalhado!E8 -> 0 | AD8: =[9]byGOVDetalhado!B8 -> 0 | AE8: =[9]byGOVDetalhado!C8 -> 0 | AF8: =[9]byGOVDetalhado!D8 -> 0 | AG8: =[9]byGOVDetalhado!E8 -> 0 | AH8: =[10]byGOVDetalhado!B8 -> 0 | AI8: =[10]byGOVDetalhado!C8 -> 0 | AJ8: =[10]byGOVDetalhado!D8 -> 0 | AK8: =[10]byGOVDetalhado!E8 -> 0 | AL8: =[11]byGOVDetalhado!B8 -> 0 | AM8: =[11]byGOVDetalhado!C8 -> 0 | AN8: =[11]byGOVDetalhado!D8 -> 0 | AO8: =[11]byGOVDetalhado!E8 -> 0 | AP8: =[12]byGOVDetalhado!B8 -> 0 | AQ8: =[12]byGOVDetalhado!C8 -> 0 | AR8: =[12]byGOVDetalhado!D8 -> 0 | AS8: =[12]byGOVDetalhado!E8 -> 0 | AT8: =[13]byGOVDetalhado!B8 -> 0 | AU8: =[13]byGOVDetalhado!C8 -> 0 | AV8: =[13]byGOVDetalhado!D8 -> 0 | AW8: =[13]byGOVDetalhado!E8 -> 0 | AX8: =[14]byGOVDetalhado!B8 -> 0 | AY8: =[14]byGOVDetalhado!C8 -> 0 | AZ8: =[14]byGOVDetalhado!D8 -> 0 | BA8: =[14]byGOVDetalhado!E8 -> 0 | BB8: =[15]byGOVDetalhado!B8 -> 0 | BC8: =[15]byGOVDetalhado!C8 -> 0 | BD8: =[15]byGOVDetalhado!D8 -> 0 | BE8: =[15]byGOVDetalhado!E8 -> 0 | BF8: =[16]byGOVDetalhado!B8 -> 0 | BG8: =[16]byGOVDetalhado!C8 -> 0 | BH8: =[16]byGOVDetalhado!D8 -> 0 | BI8: =[16]byGOVDetalhado!E8 -> 0 | BJ8: =[17]byGOVDetalhado!B8 -> 0 | BK8: =[17]byGOVDetalhado!C8 -> 0 | BL8: =[17]byGOVDetalhado!D8 -> 0 | BM8: =[17]byGOVDetalhado!E8 -> 0 | BN8: =[18]byGOVDetalhado!B8 -> 0 | BO8: =[18]byGOVDetalhado!C8 -> 0 | BP8: =[18]byGOVDetalhado!D8 -> 0 | BQ8: =[18]byGOVDetalhado!E8 -> 0 | BR8: =[19]byGOVDetalhado!B8 -> 0 | BS8: =[19]byGOVDetalhado!C8 -> 0 | BT8: =[19]byGOVDetalhado!D8 -> 0 | BU8: =[19]byGOVDetalhado!E8 -> 0 | BV8: =[20]byGOVDetalhado!B8 -> 0 | BW8: =[20]byGOVDetalhado!C8 -> 0 | BX8: =[20]byGOVDetalhado!D8 -> 0 | BY8: =[20]byGOVDetalhado!E8 -> 0 | BZ8: =[21]byGOVDetalhado!B8 -> 0 | CA8: =[21]byGOVDetalhado!C8 -> 0 | CB8: =[21]byGOVDetalhado!D8 -> 0 | CC8: =[21]byGOVDetalhado!E8 -> 0 | CD8: =[22]byGOVDetalhado!B8 -> 0 | CE8: =[22]byGOVDetalhado!C8 -> 0 | CF8: =[22]byGOVDetalhado!D8 -> 0 | CG8: =[22]byGOVDetalhado!E8 -> 0 | CH8: =[23]byGOVDetalhado!B8 -> 0 | CI8: =[23]byGOVDetalhado!C8 -> 0 | CJ8: =[23]byGOVDetalhado!D8 -> 0 | CK8: =[23]byGOVDetalhado!E8 -> 0 | CL8: =[24]byGOVDetalhado!B8 -> 0 | CM8: =[24]byGOVDetalhado!C8 -> 0 | CN8: =[24]byGOVDetalhado!D8 -> 0 | CO8: =[24]byGOVDetalhado!E8 -> 0 | CP8: =[25]byGOVDetalhado!B8 -> 0 | CQ8: =[25]byGOVDetalhado!C8 -> 0 | CR8: =[25]byGOVDetalhado!D8 -> 0 | CS8: =[25]byGOVDetalhado!E8 -> 0 | CT8: =[26]byGOVDetalhado!B8 -> 0 | CU8: =[26]byGOVDetalhado!C8 -> 0 | CV8: =[26]byGOVDetalhado!D8 -> 0 | CW8: =[26]byGOVDetalhado!E8 -> 0
A9: UNIÃO | B9: =[2]byGOVDetalhado!B9 -> 245.03204 | C9: =[2]byGOVDetalhado!C9 -> 20.378966 | D9: =[2]byGOVDetalhado!D9 -> 66.685339 | E9: =[2]byGOVDetalhado!E9 -> 1412.709 | F9: =[3]byGOVDetalhado!B9 -> 281.98373 | G9: =[3]byGOVDetalhado!C9 -> 21.431325 | H9: =[3]byGOVDetalhado!D9 -> 66.876788 | I9: =[3]byGOVDetalhado!E9 -> 1625.7505 | J9: =[4]byGOVDetalhado!B9 -> 337.12695 | K9: =[4]byGOVDetalhado!C9 -> 22.644404 | L9: =[4]byGOVDetalhado!D9 -> 68.048055 | M9: =[4]byGOVDetalhado!E9 -> 1891.0381 | N9: =[5]byGOVDetalhado!B9 -> 377.00184 | O9: =[5]byGOVDetalhado!C9 -> 21.944867 | P9: =[5]byGOVDetalhado!D9 -> 67.319971 | Q9: =[5]byGOVDetalhado!E9 -> 2087.2755 | R9: =[6]byGOVDetalhado!B9 -> 443.44386 | S9: =[6]byGOVDetalhado!C9 -> 22.650677 | T9: =[6]byGOVDetalhado!D9 -> 67.366786 | U9: =[6]byGOVDetalhado!E9 -> 2424.3631 | V9: =[7]byGOVDetalhado!B9 -> 515.78386 | W9: =[7]byGOVDetalhado!C9 -> 23.762435 | X9: =[7]byGOVDetalhado!D9 -> 68.389631 | Y9: =[7]byGOVDetalhado!E9 -> 2785.75 | Z9: =[8]byGOVDetalhado!B9 -> 564.59653 | AA9: =[8]byGOVDetalhado!C9 -> 23.43259 | AB9: =[8]byGOVDetalhado!D9 -> 68.061747 | AC9: =[8]byGOVDetalhado!E9 -> 3013.8315 | AD9: =[9]byGOVDetalhado!B9 -> 646.5957 | AE9: =[9]byGOVDetalhado!C9 -> 23.769602 | AF9: =[9]byGOVDetalhado!D9 -> 68.726862 | AG9: =[9]byGOVDetalhado!E9 -> 3412.7853 | AH9: =[10]byGOVDetalhado!B9 -> 738.74107 | AI9: =[10]byGOVDetalhado!C9 -> 23.755237 | AJ9: =[10]byGOVDetalhado!D9 -> 68.345889 | AK9: =[10]byGOVDetalhado!E9 -> 3857.0024 | AL9: =[11]byGOVDetalhado!B9 -> 745.83668 | AM9: =[11]byGOVDetalhado!C9 -> 22.377076 | AN9: =[11]byGOVDetalhado!D9 -> 67.47369 | AO9: =[11]byGOVDetalhado!E9 -> 3853.5775 | AP9: =[12]byGOVDetalhado!B9 -> 868.73679 | AQ9: =[12]byGOVDetalhado!C9 -> 22.356433 | AR9: =[12]byGOVDetalhado!D9 -> 67.272905 | AS9: =[12]byGOVDetalhado!E9 -> 4443.7165 | AT9: =[13]byGOVDetalhado!B9 -> 1017.0071 | AU9: =[13]byGOVDetalhado!C9 -> 23.238536 | AV9: =[13]byGOVDetalhado!D9 -> 68.182114 | AW9: =[13]byGOVDetalhado!E9 -> 5152.0895 | AX9: =[14]byGOVDetalhado!B9 -> 1111.1552 | AY9: =[14]byGOVDetalhado!C9 -> 23.078101 | AZ9: =[14]byGOVDetalhado!D9 -> 67.831488 | BA9: =[14]byGOVDetalhado!E9 -> 5576.8994 | BB9: =[15]byGOVDetalhado!B9 -> 1208.3874 | BC9: =[15]byGOVDetalhado!C9 -> 22.66455 | BD9: =[15]byGOVDetalhado!D9 -> 67.423076 | BE9: =[15]byGOVDetalhado!E9 -> 6010.8995 | BF9: =[16]byGOVDetalhado!B9 -> 1266.193 | BG9: =[16]byGOVDetalhado!C9 -> 21.910422 | BH9: =[16]byGOVDetalhado!D9 -> 66.649409 | BI9: =[16]byGOVDetalhado!E9 -> 6244.5232 | BJ9: =[17]byGOVDetalhado!B9 -> 1299.1238 | BK9: =[17]byGOVDetalhado!C9 -> 21.667278 | BL9: =[17]byGOVDetalhado!D9 -> 65.977824 | BM9: =[17]byGOVDetalhado!E9 -> 6354.2171 | BN9: =[18]byGOVDetalhado!B9 -> 1374.5454 | BO9: =[18]byGOVDetalhado!C9 -> 21.932351 | BP9: =[18]byGOVDetalhado!D9 -> 65.888892 | BQ9: =[18]byGOVDetalhado!E9 -> 6669.9138 | BR9: =[19]byGOVDetalhado!B9 -> 1439.7472 | BS9: =[19]byGOVDetalhado!C9 -> 21.967986 | BT9: =[19]byGOVDetalhado!D9 -> 65.341941 | BU9: =[19]byGOVDetalhado!E9 -> 6933.1638 | BV9: =[20]byGOVDetalhado!B9 -> 1550.492 | BW9: =[20]byGOVDetalhado!C9 -> 22.506204 | BX9: =[20]byGOVDetalhado!D9 -> 65.344418 | BY9: =[20]byGOVDetalhado!E9 -> 7436.5946 | BZ9: =[21]byGOVDetalhado!B9 -> 1610.6225 | CA9: =[21]byGOVDetalhado!C9 -> 21.797184 | CB9: =[21]byGOVDetalhado!D9 -> 64.504259 | CC9: =[21]byGOVDetalhado!E9 -> 7664.2615 | CD9: =[22]byGOVDetalhado!B9 -> 1541.6976 | CE9: =[22]byGOVDetalhado!C9 -> 20.259911 | CF9: =[22]byGOVDetalhado!D9 -> 62.886457 | CG9: =[22]byGOVDetalhado!E9 -> 7280.5484 | CH9: =[23]byGOVDetalhado!B9 -> 1962.2415 | CI9: =[23]byGOVDetalhado!C9 -> 22.050811 | CJ9: =[23]byGOVDetalhado!D9 -> 64.105309 | CK9: =[23]byGOVDetalhado!E9 -> 9198.6836 | CL9: =[24]byGOVDetalhado!B9 -> 2292.7229 | CM9: =[24]byGOVDetalhado!C9 -> 22.745998 | CN9: =[24]byGOVDetalhado!D9 -> 65.162002 | CO9: =[24]byGOVDetalhado!E9 -> 11289.71 | CP9: =[25]byGOVDetalhado!B9 -> 2470.2827 | CQ9: =[25]byGOVDetalhado!C9 -> 22.573381 | CR9: =[25]byGOVDetalhado!D9 -> 65.282528 | CS9: =[25]byGOVDetalhado!E9 -> 11885.945 | CT9: =[26]byGOVDetalhado!B9 -> 2735.2139 | CU9: =[26]byGOVDetalhado!C9 -> 23.288903 | CV9: =[26]byGOVDetalhado!D9 -> 64.781386 | CW9: =[26]byGOVDetalhado!E9 -> 12866.524
A10: IR | B10: =[2]byGOVDetalhado!B10 -> 48.05103 | C10: =[2]byGOVDetalhado!C10 -> 3.9963357 | D10: =[2]byGOVDetalhado!D10 -> 13.077062 | E10: =[2]byGOVDetalhado!E10 -> 277.03366 | F10: =[3]byGOVDetalhado!B10 -> 58.452662 | G10: =[3]byGOVDetalhado!C10 -> 4.4425187 | H10: =[3]byGOVDetalhado!D10 -> 13.86295 | I10: =[3]byGOVDetalhado!E10 -> 337.00328 | J10: =[4]byGOVDetalhado!B10 -> 75.551116 | K10: =[4]byGOVDetalhado!C10 -> 5.074676 | L10: =[4]byGOVDetalhado!D10 -> 15.249764 | M10: =[4]byGOVDetalhado!E10 -> 423.78706 | N10: =[5]byGOVDetalhado!B10 -> 82.42169 | O10: =[5]byGOVDetalhado!C10 -> 4.7976769 | P10: =[5]byGOVDetalhado!D10 -> 14.717768 | Q10: =[5]byGOVDetalhado!E10 -> 456.32874 | R10: =[6]byGOVDetalhado!B10 -> 90.362734 | S10: =[6]byGOVDetalhado!C10 -> 4.6156398 | T10: =[6]byGOVDetalhado!D10 -> 13.727661 | U10: =[6]byGOVDetalhado!E10 -> 494.02438 | V10: =[7]byGOVDetalhado!B10 -> 112.57153 | W10: =[7]byGOVDetalhado!C10 -> 5.18623 | X10: =[7]byGOVDetalhado!D10 -> 14.926263 | Y10: =[7]byGOVDetalhado!E10 -> 607.99914 | Z10: =[8]byGOVDetalhado!B10 -> 122.18487 | AA10: =[8]byGOVDetalhado!C10 -> 5.0710689 | AB10: =[8]byGOVDetalhado!D10 -> 14.729307 | AC10: =[8]byGOVDetalhado!E10 -> 652.22612 | AD10: =[9]byGOVDetalhado!B10 -> 143.96079 | AE10: =[9]byGOVDetalhado!C10 -> 5.2921644 | AF10: =[9]byGOVDetalhado!D10 -> 15.301638 | AG10: =[9]byGOVDetalhado!E10 -> 759.83689 | AH10: =[10]byGOVDetalhado!B10 -> 174.29937 | AI10: =[10]byGOVDetalhado!C10 -> 5.6048364 | AJ10: =[10]byGOVDetalhado!D10 -> 16.125603 | AK10: =[10]byGOVDetalhado!E10 -> 910.02532 | AL10: =[11]byGOVDetalhado!B10 -> 172.60142 | AM10: =[11]byGOVDetalhado!C10 -> 5.1784998 | AN10: =[11]byGOVDetalhado!D10 -> 15.614752 | AO10: =[11]byGOVDetalhado!E10 -> 891.79435 | AP10: =[12]byGOVDetalhado!B10 -> 190.54988 | AQ10: =[12]byGOVDetalhado!C10 -> 4.9036896 | AR10: =[12]byGOVDetalhado!D10 -> 14.755728 | AS10: =[12]byGOVDetalhado!E10 -> 974.69065 | AT10: =[13]byGOVDetalhado!B10 -> 231.29945 | AU10: =[13]byGOVDetalhado!C10 -> 5.2851751 | AV10: =[13]byGOVDetalhado!D10 -> 15.506761 | AW10: =[13]byGOVDetalhado!E10 -> 1171.7474 | AX10: =[14]byGOVDetalhado!B10 -> 235.64137 | AY10: =[14]byGOVDetalhado!C10 -> 4.8941457 | AZ10: =[14]byGOVDetalhado!D10 -> 14.384944 | BA10: =[14]byGOVDetalhado!E10 -> 1182.6865 | BB10: =[15]byGOVDetalhado!B10 -> 259.61411 | BC10: =[15]byGOVDetalhado!C10 -> 4.8693297 | BD10: =[15]byGOVDetalhado!D10 -> 14.485405 | BE10: =[15]byGOVDetalhado!E10 -> 1291.4023 | BF10: =[16]byGOVDetalhado!B10 -> 277.4003 | BG10: =[16]byGOVDetalhado!C10 -> 4.8001827 | BH10: =[16]byGOVDetalhado!D10 -> 14.601697 | BI10: =[16]byGOVDetalhado!E10 -> 1368.0637 | BJ10: =[17]byGOVDetalhado!B10 -> 294.59894 | BK10: =[17]byGOVDetalhado!C10 -> 4.9134324 | BL10: =[17]byGOVDetalhado!D10 -> 14.96162 | BM10: =[17]byGOVDetalhado!E10 -> 1440.9293 | BN10: =[18]byGOVDetalhado!B10 -> 333.76771 | BO10: =[18]byGOVDetalhado!C10 -> 5.325623 | BP10: =[18]byGOVDetalhado!D10 -> 15.999169 | BQ10: =[18]byGOVDetalhado!E10 -> 1619.5914 | BR10: =[19]byGOVDetalhado!B10 -> 352.07921 | BS10: =[19]byGOVDetalhado!C10 -> 5.3721035 | BT10: =[19]byGOVDetalhado!D10 -> 15.978874 | BU10: =[19]byGOVDetalhado!E10 -> 1695.4524 | BV10: =[20]byGOVDetalhado!B10 -> 350.80171 | BW10: =[20]byGOVDetalhado!C10 -> 5.0920705 | BX10: =[20]byGOVDetalhado!D10 -> 14.784296 | BY10: =[20]byGOVDetalhado!E10 -> 1682.5433 | BZ10: =[21]byGOVDetalhado!B10 -> 388.1289 | CA10: =[21]byGOVDetalhado!C10 -> 5.2527003 | CB10: =[21]byGOVDetalhado!D10 -> 15.54428 | CC10: =[21]byGOVDetalhado!E10 -> 1846.9389 | CD10: =[22]byGOVDetalhado!B10 -> 374.91586 | CE10: =[22]byGOVDetalhado!C10 -> 4.9268819 | CF10: =[22]byGOVDetalhado!D10 -> 15.292967 | CG10: =[22]byGOVDetalhado!E10 -> 1770.5114 | CH10: =[23]byGOVDetalhado!B10 -> 506.31434 | CI10: =[23]byGOVDetalhado!C10 -> 5.689739 | CJ10: =[23]byGOVDetalhado!D10 -> 16.541001 | CK10: =[23]byGOVDetalhado!E10 -> 2373.5231 | CL10: =[24]byGOVDetalhado!B10 -> 653.46837 | CM10: =[24]byGOVDetalhado!C10 -> 6.4830295 | CN10: =[24]byGOVDetalhado!D10 -> 18.572374 | CO10: =[24]byGOVDetalhado!E10 -> 3217.7759 | CP10: =[25]byGOVDetalhado!B10 -> 731.63772 | CQ10: =[25]byGOVDetalhado!C10 -> 6.6856869 | CR10: =[25]byGOVDetalhado!D10 -> 19.335099 | CS10: =[25]byGOVDetalhado!E10 -> 3520.3281 | CT10: =[26]byGOVDetalhado!B10 -> 764.55033 | CU10: =[26]byGOVDetalhado!C10 -> 6.5097427 | CV10: =[26]byGOVDetalhado!D10 -> 18.107772 | CW10: =[26]byGOVDetalhado!E10 -> 3596.4665
A11: IPI | B11: =[2]byGOVDetalhado!B11 -> 17.553938 | C11: =[2]byGOVDetalhado!C11 -> 1.459936 | D11: =[2]byGOVDetalhado!D11 -> 4.7772949 | E11: =[2]byGOVDetalhado!E11 -> 101.20557 | F11: =[3]byGOVDetalhado!B11 -> 18.83749 | G11: =[3]byGOVDetalhado!C11 -> 1.4316867 | H11: =[3]byGOVDetalhado!D11 -> 4.4676011 | I11: =[3]byGOVDetalhado!E11 -> 108.60576 | J11: =[4]byGOVDetalhado!B11 -> 18.471562 | K11: =[4]byGOVDetalhado!C11 -> 1.2407122 | L11: =[4]byGOVDetalhado!D11 -> 3.7284289 | M11: =[4]byGOVDetalhado!E11 -> 103.61209 | N11: =[5]byGOVDetalhado!B11 -> 17.923868 | O11: =[5]byGOVDetalhado!C11 -> 1.0433289 | P11: =[5]byGOVDetalhado!D11 -> 3.2006058 | Q11: =[5]byGOVDetalhado!E11 -> 99.235725 | R11: =[6]byGOVDetalhado!B11 -> 21.059034 | S11: =[6]byGOVDetalhado!C11 -> 1.0756748 | T11: =[6]byGOVDetalhado!D11 -> 3.1992312 | U11: =[6]byGOVDetalhado!E11 -> 115.13238 | V11: =[7]byGOVDetalhado!B11 -> 24.061421 | W11: =[7]byGOVDetalhado!C11 -> 1.1085224 | X11: =[7]byGOVDetalhado!D11 -> 3.1903901 | Y11: =[7]byGOVDetalhado!E11 -> 129.9558 | Z11: =[8]byGOVDetalhado!B11 -> 26.780064 | AA11: =[8]byGOVDetalhado!C11 -> 1.1114596 | AB11: =[8]byGOVDetalhado!D11 -> 3.2283194 | AC11: =[8]byGOVDetalhado!E11 -> 142.9527 | AD11: =[9]byGOVDetalhado!B11 -> 31.240028 | AE11: =[9]byGOVDetalhado!C11 -> 1.1484194 | AF11: =[9]byGOVDetalhado!D11 -> 3.3205125 | AG11: =[9]byGOVDetalhado!E11 -> 164.88744 | AH11: =[10]byGOVDetalhado!B11 -> 36.695285 | AI11: =[10]byGOVDetalhado!C11 -> 1.1799875 | AJ11: =[10]byGOVDetalhado!D11 -> 3.3949269 | AK11: =[10]byGOVDetalhado!E11 -> 191.58784 | AL11: =[11]byGOVDetalhado!B11 -> 27.598789 | AM11: =[11]byGOVDetalhado!C11 -> 0.82803679 | AN11: =[11]byGOVDetalhado!D11 -> 2.4967828 | AO11: =[11]byGOVDetalhado!E11 -> 142.597 | AP11: =[12]byGOVDetalhado!B11 -> 37.25502 | AQ11: =[12]byGOVDetalhado!C11 -> 0.95873615 | AR11: =[12]byGOVDetalhado!D11 -> 2.8849399 | AS11: =[12]byGOVDetalhado!E11 -> 190.56491 | AT11: =[13]byGOVDetalhado!B11 -> 41.140073 | AU11: =[13]byGOVDetalhado!C11 -> 0.94004758 | AV11: =[13]byGOVDetalhado!D11 -> 2.7581097 | AW11: =[13]byGOVDetalhado!E11 -> 208.41284 | AX11: =[14]byGOVDetalhado!B11 -> 42.566775 | AY11: =[14]byGOVDetalhado!C11 -> 0.88408924 | AZ11: =[14]byGOVDetalhado!D11 -> 2.5985279 | BA11: =[14]byGOVDetalhado!E11 -> 213.64309 | BB11: =[15]byGOVDetalhado!B11 -> 42.706265 | BC11: =[15]byGOVDetalhado!C11 -> 0.80099994 | BD11: =[15]byGOVDetalhado!D11 -> 2.3828349 | BE11: =[15]byGOVDetalhado!E11 -> 212.4344 | BF11: =[16]byGOVDetalhado!B11 -> 48.910482 | BG11: =[16]byGOVDetalhado!C11 -> 0.84635543 | BH11: =[16]byGOVDetalhado!D11 -> 2.5745323 | BI11: =[16]byGOVDetalhado!E11 -> 241.21334 | BJ11: =[17]byGOVDetalhado!B11 -> 47.96111 | BK11: =[17]byGOVDetalhado!C11 -> 0.7999135 | BL11: =[17]byGOVDetalhado!D11 -> 2.4357722 | BM11: =[17]byGOVDetalhado!E11 -> 234.58526 | BN11: =[18]byGOVDetalhado!B11 -> 41.757059 | BO11: =[18]byGOVDetalhado!C11 -> 0.66627881 | BP11: =[18]byGOVDetalhado!D11 -> 2.0016264 | BQ11: =[18]byGOVDetalhado!E11 -> 202.62407 | BR11: =[19]byGOVDetalhado!B11 -> 47.576969 | BS11: =[19]byGOVDetalhado!C11 -> 0.72594006 | BT11: =[19]byGOVDetalhado!D11 -> 2.1592481 | BU11: =[19]byGOVDetalhado!E11 -> 229.10891 | BV11: =[20]byGOVDetalhado!B11 -> 53.762111 | BW11: =[20]byGOVDetalhado!C11 -> 0.7803852 | BX11: =[20]byGOVDetalhado!D11 -> 2.2657671 | BY11: =[20]byGOVDetalhado!E11 -> 257.85816 | BZ11: =[21]byGOVDetalhado!B11 -> 52.258162 | CA11: =[21]byGOVDetalhado!C11 -> 0.70723015 | CB11: =[21]byGOVDetalhado!D11 -> 2.0929014 | CC11: =[21]byGOVDetalhado!E11 -> 248.67417 | CD11: =[22]byGOVDetalhado!B11 -> 55.67597 | CE11: =[22]byGOVDetalhado!C11 -> 0.73165465 | CF11: =[22]byGOVDetalhado!D11 -> 2.271045 | CG11: =[22]byGOVDetalhado!E11 -> 262.9255 | CH11: =[23]byGOVDetalhado!B11 -> 70.086019 | CI11: =[23]byGOVDetalhado!C11 -> 0.78759601 | CJ11: =[23]byGOVDetalhado!D11 -> 2.2896702 | CK11: =[23]byGOVDetalhado!E11 -> 328.55238 | CL11: =[24]byGOVDetalhado!B11 -> 58.255361 | CM11: =[24]byGOVDetalhado!C11 -> 0.57794874 | CN11: =[24]byGOVDetalhado!D11 -> 1.655689 | CO11: =[24]byGOVDetalhado!E11 -> 286.8581 | CP11: =[25]byGOVDetalhado!B11 -> 59.723119 | CQ11: =[25]byGOVDetalhado!C11 -> 0.54574835 | CR11: =[25]byGOVDetalhado!D11 -> 1.5783117 | CS11: =[25]byGOVDetalhado!E11 -> 287.36213 | CT11: =[26]byGOVDetalhado!B11 -> 82.173979 | CU11: =[26]byGOVDetalhado!C11 -> 0.69966807 | CV11: =[26]byGOVDetalhado!D11 -> 1.9462259 | CW11: =[26]byGOVDetalhado!E11 -> 386.54873
A12: IOF | B12: =[2]byGOVDetalhado!B12 -> 3.0909899 | C12: =[2]byGOVDetalhado!C12 -> 0.25707323 | D12: =[2]byGOVDetalhado!D12 -> 0.84121126 | E12: =[2]byGOVDetalhado!E12 -> 17.82081 | F12: =[3]byGOVDetalhado!B12 -> 3.5519022 | G12: =[3]byGOVDetalhado!C12 -> 0.26995164 | H12: =[3]byGOVDetalhado!D12 -> 0.84238837 | I12: =[3]byGOVDetalhado!E12 -> 20.478156 | J12: =[4]byGOVDetalhado!B12 -> 3.993263 | K12: =[4]byGOVDetalhado!C12 -> 0.26822259 | L12: =[4]byGOVDetalhado!D12 -> 0.80602806 | M12: =[4]byGOVDetalhado!E12 -> 22.399314 | N12: =[5]byGOVDetalhado!B12 -> 4.4184168 | O12: =[5]byGOVDetalhado!C12 -> 0.25719123 | P12: =[5]byGOVDetalhado!D12 -> 0.78898205 | Q12: =[5]byGOVDetalhado!E12 -> 24.462621 | R12: =[6]byGOVDetalhado!B12 -> 5.2309541 | S12: =[6]byGOVDetalhado!C12 -> 0.267192 | T12: =[6]byGOVDetalhado!D12 -> 0.79467234 | U12: =[6]byGOVDetalhado!E12 -> 28.598281 | V12: =[7]byGOVDetalhado!B12 -> 5.9653248 | W12: =[7]byGOVDetalhado!C12 -> 0.27482567 | X12: =[7]byGOVDetalhado!D12 -> 0.79096381 | Y12: =[7]byGOVDetalhado!E12 -> 32.218735 | Z12: =[8]byGOVDetalhado!B12 -> 6.7375805 | AA12: =[8]byGOVDetalhado!C12 -> 0.27963147 | AB12: =[8]byGOVDetalhado!D12 -> 0.81221097 | AC12: =[8]byGOVDetalhado!E12 -> 35.965386 | AD12: =[9]byGOVDetalhado!B12 -> 7.8165821 | AE12: =[9]byGOVDetalhado!C12 -> 0.28734656 | AF12: =[9]byGOVDetalhado!D12 -> 0.83082699 | AG12: =[9]byGOVDetalhado!E12 -> 41.256563 | AH12: =[10]byGOVDetalhado!B12 -> 20.167891 | AI12: =[10]byGOVDetalhado!C12 -> 0.64852634 | AJ12: =[10]byGOVDetalhado!D12 -> 1.8658669 | AK12: =[10]byGOVDetalhado!E12 -> 105.29752 | AL12: =[11]byGOVDetalhado!B12 -> 19.193098 | AM12: =[11]byGOVDetalhado!C12 -> 0.57584377 | AN12: =[11]byGOVDetalhado!D12 -> 1.7363441 | AO12: =[11]byGOVDetalhado!E12 -> 99.166601 | AP12: =[12]byGOVDetalhado!B12 -> 26.529575 | AQ12: =[12]byGOVDetalhado!C12 -> 0.68272309 | AR12: =[12]byGOVDetalhado!D12 -> 2.054387 | AS12: =[12]byGOVDetalhado!E12 -> 135.70268 | AT12: =[13]byGOVDetalhado!B12 -> 31.870478 | AU12: =[13]byGOVDetalhado!C12 -> 0.72823804 | AV12: =[13]byGOVDetalhado!D12 -> 2.1366582 | AW12: =[13]byGOVDetalhado!E12 -> 161.4537 | AX12: =[14]byGOVDetalhado!B12 -> 30.9984 | AY12: =[14]byGOVDetalhado!C12 -> 0.64382026 | AZ12: =[14]byGOVDetalhado!D12 -> 1.8923258 | BA12: =[14]byGOVDetalhado!E12 -> 155.58129 | BB12: =[15]byGOVDetalhado!B12 -> 29.41226 | BC12: =[15]byGOVDetalhado!C12 -> 0.55165719 | BD12: =[15]byGOVDetalhado!D12 -> 1.6410838 | BE12: =[15]byGOVDetalhado!E12 -> 146.30584 | BF12: =[16]byGOVDetalhado!B12 -> 29.739887 | BG12: =[16]byGOVDetalhado!C12 -> 0.51462413 | BH12: =[16]byGOVDetalhado!D12 -> 1.5654374 | BI12: =[16]byGOVDetalhado!E12 -> 146.66912 | BJ12: =[17]byGOVDetalhado!B12 -> 34.680211 | BK12: =[17]byGOVDetalhado!C12 -> 0.57840966 | BL12: =[17]byGOVDetalhado!D12 -> 1.7612832 | BM12: =[17]byGOVDetalhado!E12 -> 169.62632 | BN12: =[18]byGOVDetalhado!B12 -> 33.642583 | BO12: =[18]byGOVDetalhado!C12 -> 0.53680362 | BP12: =[18]byGOVDetalhado!D12 -> 1.6126587 | BQ12: =[18]byGOVDetalhado!E12 -> 163.24898 | BR12: =[19]byGOVDetalhado!B12 -> 34.408095 | BS12: =[19]byGOVDetalhado!C12 -> 0.52500642 | BT12: =[19]byGOVDetalhado!D12 -> 1.5615878 | BU12: =[19]byGOVDetalhado!E12 -> 165.69364 | BV12: =[20]byGOVDetalhado!B12 -> 36.612379 | BW12: =[20]byGOVDetalhado!C12 -> 0.53144786 | BX12: =[20]byGOVDetalhado!D12 -> 1.5430035 | BY12: =[20]byGOVDetalhado!E12 -> 175.60323 | BZ12: =[21]byGOVDetalhado!B12 -> 40.941984 | CA12: =[21]byGOVDetalhado!C12 -> 0.55408388 | CB12: =[21]byGOVDetalhado!D12 -> 1.6396967 | CC12: =[21]byGOVDetalhado!E12 -> 194.82534 | CD12: =[22]byGOVDetalhado!B12 -> 21.944817 | CE12: =[22]byGOVDetalhado!C12 -> 0.28838343 | CF12: =[22]byGOVDetalhado!D12 -> 0.89513783 | CG12: =[22]byGOVDetalhado!E12 -> 103.63271 | CH12: =[23]byGOVDetalhado!B12 -> 49.012228 | CI12: =[23]byGOVDetalhado!C12 -> 0.55077797 | CJ12: =[23]byGOVDetalhado!D12 -> 1.6012015 | CK12: =[23]byGOVDetalhado!E12 -> 229.76172 | CL12: =[24]byGOVDetalhado!B12 -> 58.960077 | CM12: =[24]byGOVDetalhado!C12 -> 0.58494021 | CN12: =[24]byGOVDetalhado!D12 -> 1.6757179 | CO12: =[24]byGOVDetalhado!E12 -> 290.32824 | CP12: =[25]byGOVDetalhado!B12 -> 61.012797 | CQ12: =[25]byGOVDetalhado!C12 -> 0.55753339 | CR12: =[25]byGOVDetalhado!D12 -> 1.6123942 | CS12: =[25]byGOVDetalhado!E12 -> 293.56751 | CT12: =[26]byGOVDetalhado!B12 -> 67.40223 | CU12: =[26]byGOVDetalhado!C12 -> 0.57389442 | CV12: =[26]byGOVDetalhado!D12 -> 1.5963687 | CW12: =[26]byGOVDetalhado!E12 -> 317.062
A13: Imp. Sobre Comércio Exterior | B13: =[2]byGOVDetalhado!B13 -> 8.4307442 | C13: =[2]byGOVDetalhado!C13 -> 0.70117298 | D13: =[2]byGOVDetalhado!D13 -> 2.2944225 | E13: =[2]byGOVDetalhado!E13 -> 48.606657 | F13: =[3]byGOVDetalhado!B13 -> 9.0965329 | G13: =[3]byGOVDetalhado!C13 -> 0.69135461 | H13: =[3]byGOVDetalhado!D13 -> 2.157383 | I13: =[3]byGOVDetalhado!E13 -> 52.445198 | J13: =[4]byGOVDetalhado!B13 -> 7.9535269 | K13: =[4]byGOVDetalhado!C13 -> 0.53422867 | L13: =[4]byGOVDetalhado!D13 -> 1.6053954 | M13: =[4]byGOVDetalhado!E13 -> 44.613527 | N13: =[5]byGOVDetalhado!B13 -> 8.1282986 | O13: =[5]byGOVDetalhado!C13 -> 0.47313941 | P13: =[5]byGOVDetalhado!D13 -> 1.4514434 | Q13: =[5]byGOVDetalhado!E13 -> 45.002429 | R13: =[6]byGOVDetalhado!B13 -> 9.2158879 | S13: =[6]byGOVDetalhado!C13 -> 0.47073851 | T13: =[6]byGOVDetalhado!D13 -> 1.4000526 | U13: =[6]byGOVDetalhado!E13 -> 50.384413 | V13: =[7]byGOVDetalhado!B13 -> 8.9411287 | W13: =[7]byGOVDetalhado!C13 -> 0.41192253 | X13: =[7]byGOVDetalhado!D13 -> 1.1855363 | Y13: =[7]byGOVDetalhado!E13 -> 48.29106 | Z13: =[8]byGOVDetalhado!B13 -> 9.8571358 | AA13: =[8]byGOVDetalhado!C13 -> 0.40910315 | AB13: =[8]byGOVDetalhado!D13 -> 1.1882713 | AC13: =[8]byGOVDetalhado!E13 -> 52.617656 | AD13: =[9]byGOVDetalhado!B13 -> 12.21607 | AE13: =[9]byGOVDetalhado!C13 -> 0.44907679 | AF13: =[9]byGOVDetalhado!D13 -> 1.2984499 | AG13: =[9]byGOVDetalhado!E13 -> 64.477421 | AH13: =[10]byGOVDetalhado!B13 -> 17.10149 | AI13: =[10]byGOVDetalhado!C13 -> 0.54992198 | AJ13: =[10]byGOVDetalhado!D13 -> 1.5821735 | AK13: =[10]byGOVDetalhado!E13 -> 89.287697 | AL13: =[11]byGOVDetalhado!B13 -> 15.806918 | AM13: =[11]byGOVDetalhado!C13 -> 0.47424943 | AN13: =[11]byGOVDetalhado!D13 -> 1.4300063 | AO13: =[11]byGOVDetalhado!E13 -> 81.670943 | AP13: =[12]byGOVDetalhado!B13 -> 21.080739 | AQ13: =[12]byGOVDetalhado!C13 -> 0.54250049 | AR13: =[12]byGOVDetalhado!D13 -> 1.6324422 | AS13: =[12]byGOVDetalhado!E13 -> 107.83108 | AT13: =[13]byGOVDetalhado!B13 -> 26.644493 | AU13: =[13]byGOVDetalhado!C13 -> 0.60882467 | AV13: =[13]byGOVDetalhado!D13 -> 1.7862981 | AW13: =[13]byGOVDetalhado!E13 -> 134.97921 | AX13: =[14]byGOVDetalhado!B13 -> 31.085492 | AY13: =[14]byGOVDetalhado!C13 -> 0.64562912 | AZ13: =[14]byGOVDetalhado!D13 -> 1.8976425 | BA13: =[14]byGOVDetalhado!E13 -> 156.01841 | BB13: =[15]byGOVDetalhado!B13 -> 36.709334 | BC13: =[15]byGOVDetalhado!C13 -> 0.68852134 | BD13: =[15]byGOVDetalhado!D13 -> 2.0482307 | BE13: =[15]byGOVDetalhado!E13 -> 182.60378 | BF13: =[16]byGOVDetalhado!B13 -> 36.764846 | BG13: =[16]byGOVDetalhado!C13 -> 0.63618524 | BH13: =[16]byGOVDetalhado!D13 -> 1.9352147 | BI13: =[16]byGOVDetalhado!E13 -> 181.31433 | BJ13: =[17]byGOVDetalhado!B13 -> 38.963128 | BK13: =[17]byGOVDetalhado!C13 -> 0.64984177 | BL13: =[17]byGOVDetalhado!D13 -> 1.9787971 | BM13: =[17]byGOVDetalhado!E13 -> 190.57474 | BN13: =[18]byGOVDetalhado!B13 -> 31.443843 | BO13: =[18]byGOVDetalhado!C13 -> 0.50172035 | BP13: =[18]byGOVDetalhado!D13 -> 1.507262 | BQ13: =[18]byGOVDetalhado!E13 -> 152.5797 | BR13: =[19]byGOVDetalhado!B13 -> 32.430856 | BS13: =[19]byGOVDetalhado!C13 -> 0.49483726 | BT13: =[19]byGOVDetalhado!D13 -> 1.4718521 | BU13: =[19]byGOVDetalhado!E13 -> 156.17216 | BV13: =[20]byGOVDetalhado!B13 -> 40.694891 | BW13: =[20]byGOVDetalhado!C13 -> 0.59070766 | BX13: =[20]byGOVDetalhado!D13 -> 1.7150581 | BY13: =[20]byGOVDetalhado!E13 -> 195.18411 | BZ13: =[21]byGOVDetalhado!B13 -> 42.92663 | CA13: =[21]byGOVDetalhado!C13 -> 0.58094287 | CB13: =[21]byGOVDetalhado!D13 -> 1.7191803 | CC13: =[21]byGOVDetalhado!E13 -> 204.26941 | CD13: =[22]byGOVDetalhado!B13 -> 45.713058 | CE13: =[22]byGOVDetalhado!C13 -> 0.60072902 | CF13: =[22]byGOVDetalhado!D13 -> 1.8646538 | CG13: =[22]byGOVDetalhado!E13 -> 215.87641 | CH13: =[23]byGOVDetalhado!B13 -> 62.028225 | CI13: =[23]byGOVDetalhado!C13 -> 0.69704605 | CJ13: =[23]byGOVDetalhado!D13 -> 2.0264267 | CK13: =[23]byGOVDetalhado!E13 -> 290.7787 | CL13: =[24]byGOVDetalhado!B13 -> 59.015768 | CM13: =[24]byGOVDetalhado!C13 -> 0.5854927 | CN13: =[24]byGOVDetalhado!D13 -> 1.6773007 | CO13: =[24]byGOVDetalhado!E13 -> 290.60246 | CP13: =[25]byGOVDetalhado!B13 -> 58.575786 | CQ13: =[25]byGOVDetalhado!C13 -> 0.53526405 | CR13: =[25]byGOVDetalhado!D13 -> 1.547991 | CS13: =[25]byGOVDetalhado!E13 -> 281.84165 | CT13: =[26]byGOVDetalhado!B13 -> 77.507333 | CU13: =[26]byGOVDetalhado!C13 -> 0.65993405 | CV13: =[26]byGOVDetalhado!D13 -> 1.8357001 | CW13: =[26]byGOVDetalhado!E13 -> 364.5967
A14: ITR | B14: =[2]byGOVDetalhado!B14 -> 0.23082787 | C14: =[2]byGOVDetalhado!C14 -> 0.019197625 | D14: =[2]byGOVDetalhado!D14 -> 0.062819682 | E14: =[2]byGOVDetalhado!E14 -> 1.3308162 | F14: =[3]byGOVDetalhado!B14 -> 0.18998403 | G14: =[3]byGOVDetalhado!C14 -> 0.014439164 | H14: =[3]byGOVDetalhado!D14 -> 0.045057641 | I14: =[3]byGOVDetalhado!E14 -> 1.0953349 | J14: =[4]byGOVDetalhado!B14 -> 0.18918939 | K14: =[4]byGOVDetalhado!C14 -> 0.01270762 | L14: =[4]byGOVDetalhado!D14 -> 0.038187307 | M14: =[4]byGOVDetalhado!E14 -> 1.0612155 | N14: =[5]byGOVDetalhado!B14 -> 0.22792358 | O14: =[5]byGOVDetalhado!C14 -> 0.013267183 | P14: =[5]byGOVDetalhado!D14 -> 0.040699558 | Q14: =[5]byGOVDetalhado!E14 -> 1.2619018 | R14: =[6]byGOVDetalhado!B14 -> 0.23977249 | S14: =[6]byGOVDetalhado!C14 -> 0.012247343 | T14: =[6]byGOVDetalhado!D14 -> 0.036425584 | U14: =[6]byGOVDetalhado!E14 -> 1.3108662 | V14: =[7]byGOVDetalhado!B14 -> 0.27007668 | W14: =[7]byGOVDetalhado!C14 -> 0.012442575 | X14: =[7]byGOVDetalhado!D14 -> 0.035810435 | Y14: =[7]byGOVDetalhado!E14 -> 1.4586848 | Z14: =[8]byGOVDetalhado!B14 -> 0.28402332 | AA14: =[8]byGOVDetalhado!C14 -> 0.01178789 | AB14: =[8]byGOVDetalhado!D14 -> 0.034238827 | AC14: =[8]byGOVDetalhado!E14 -> 1.5161241 | AD14: =[9]byGOVDetalhado!B14 -> 0.31279981 | AE14: =[9]byGOVDetalhado!C14 -> 0.011498881 | AF14: =[9]byGOVDetalhado!D14 -> 0.033247591 | AG14: =[9]byGOVDetalhado!E14 -> 1.6509831 | AH14: =[10]byGOVDetalhado!B14 -> 0.39541172 | AI14: =[10]byGOVDetalhado!C14 -> 0.012715009 | AJ14: =[10]byGOVDetalhado!D14 -> 0.036582189 | AK14: =[10]byGOVDetalhado!E14 -> 2.0644634 | AL14: =[11]byGOVDetalhado!B14 -> 0.4088979 | AM14: =[11]byGOVDetalhado!C14 -> 0.01226802 | AN14: =[11]byGOVDetalhado!D14 -> 0.036991812 | AO14: =[11]byGOVDetalhado!E14 -> 2.1126874 | AP14: =[12]byGOVDetalhado!B14 -> 0.47598755 | AQ14: =[12]byGOVDetalhado!C14 -> 0.012249261 | AR14: =[12]byGOVDetalhado!D14 -> 0.03685934 | AS14: =[12]byGOVDetalhado!E14 -> 2.4347463 | AT14: =[13]byGOVDetalhado!B14 -> 0.54624142 | AU14: =[13]byGOVDetalhado!C14 -> 0.012481575 | AV14: =[13]byGOVDetalhado!D14 -> 0.036621077 | AW14: =[13]byGOVDetalhado!E14 -> 2.7672223 | AX14: =[14]byGOVDetalhado!B14 -> 0.60943849 | AY14: =[14]byGOVDetalhado!C14 -> 0.012657713 | AZ14: =[14]byGOVDetalhado!D14 -> 0.037203733 | BA14: =[14]byGOVDetalhado!E14 -> 3.0587782 | BB14: =[15]byGOVDetalhado!B14 -> 0.75283784 | BC14: =[15]byGOVDetalhado!C14 -> 0.014120248 | BD14: =[15]byGOVDetalhado!D14 -> 0.042005272 | BE14: =[15]byGOVDetalhado!E14 -> 3.7448524 | BF14: =[16]byGOVDetalhado!B14 -> 0.89117742 | BG14: =[16]byGOVDetalhado!C14 -> 0.015421088 | BH14: =[16]byGOVDetalhado!D14 -> 0.046909475 | BI14: =[16]byGOVDetalhado!E14 -> 4.3950473 | BJ14: =[17]byGOVDetalhado!B14 -> 1.1012954 | BK14: =[17]byGOVDetalhado!C14 -> 0.018367821 | BL14: =[17]byGOVDetalhado!D14 -> 0.055930832 | BM14: =[17]byGOVDetalhado!E14 -> 5.3866076 | BN14: =[18]byGOVDetalhado!B14 -> 1.1189416 | BO14: =[18]byGOVDetalhado!C14 -> 0.017853917 | BP14: =[18]byGOVDetalhado!D14 -> 0.053636511 | BQ14: =[18]byGOVDetalhado!E14 -> 5.4296088 | BR14: =[19]byGOVDetalhado!B14 -> 1.2712081 | BS14: =[19]byGOVDetalhado!C14 -> 0.019396378 | BT14: =[19]byGOVDetalhado!D14 -> 0.057692909 | BU14: =[19]byGOVDetalhado!E14 -> 6.1215566 | BV14: =[20]byGOVDetalhado!B14 -> 1.413985 | BW14: =[20]byGOVDetalhado!C14 -> 0.020524733 | BX14: =[20]byGOVDetalhado!D14 -> 0.059591421 | BY14: =[20]byGOVDetalhado!E14 -> 6.7818684 | BZ14: =[21]byGOVDetalhado!B14 -> 1.6252833 | CA14: =[21]byGOVDetalhado!C14 -> 0.021995595 | CB14: =[21]byGOVDetalhado!D14 -> 0.065091413 | CC14: =[21]byGOVDetalhado!E14 -> 7.7340259 | CD14: =[22]byGOVDetalhado!B14 -> 1.757006 | CE14: =[22]byGOVDetalhado!C14 -> 0.023089344 | CF14: =[22]byGOVDetalhado!D14 -> 0.071668976 | CG14: =[22]byGOVDetalhado!E14 -> 8.2973261 | CH14: =[23]byGOVDetalhado!B14 -> 2.1600571 | CI14: =[23]byGOVDetalhado!C14 -> 0.024273776 | CJ14: =[23]byGOVDetalhado!D14 -> 0.070567833 | CK14: =[23]byGOVDetalhado!E14 -> 10.126013 | CL14: =[24]byGOVDetalhado!B14 -> 2.5880176 | CM14: =[24]byGOVDetalhado!C14 -> 0.025675604 | CN14: =[24]byGOVDetalhado!D14 -> 0.073554643 | CO14: =[24]byGOVDetalhado!E14 -> 12.743786 | CP14: =[25]byGOVDetalhado!B14 -> 3.0321212 | CQ14: =[25]byGOVDetalhado!C14 -> 0.027707447 | CR14: =[25]byGOVDetalhado!D14 -> 0.080130318 | CS14: =[25]byGOVDetalhado!E14 -> 14.589272 | CT14: =[26]byGOVDetalhado!B14 -> 3.2455194 | CU14: =[26]byGOVDetalhado!C14 -> 0.027633885 | CV14: =[26]byGOVDetalhado!D14 -> 0.076867569 | CW14: =[26]byGOVDetalhado!E14 -> 15.267016
A15: Taxas | B15: =[2]byGOVDetalhado!B15 -> 1.3282668 | C15: =[2]byGOVDetalhado!C15 -> 0.11047006 | D15: =[2]byGOVDetalhado!D15 -> 0.36148711 | E15: =[2]byGOVDetalhado!E15 -> 7.6579966 | F15: =[3]byGOVDetalhado!B15 -> 1.4958849 | G15: =[3]byGOVDetalhado!C15 -> 0.11369023 | H15: =[3]byGOVDetalhado!D15 -> 0.35477217 | I15: =[3]byGOVDetalhado!E15 -> 8.6243827 | J15: =[4]byGOVDetalhado!B15 -> 1.7383784 | K15: =[4]byGOVDetalhado!C15 -> 0.11676475 | L15: =[4]byGOVDetalhado!D15 -> 0.35088642 | M15: =[4]byGOVDetalhado!E15 -> 9.7510442 | N15: =[5]byGOVDetalhado!B15 -> 2.0708408 | O15: =[5]byGOVDetalhado!C15 -> 0.12054139 | P15: =[5]byGOVDetalhado!D15 -> 0.36978317 | Q15: =[5]byGOVDetalhado!E15 -> 11.465236 | R15: =[6]byGOVDetalhado!B15 -> 2.565985 | S15: =[6]byGOVDetalhado!C15 -> 0.131068 | T15: =[6]byGOVDetalhado!D15 -> 0.38981747 | U15: =[6]byGOVDetalhado!E15 -> 14.028561 | V15: =[7]byGOVDetalhado!B15 -> 3.2479439 | W15: =[7]byGOVDetalhado!C15 -> 0.1496345 | X15: =[7]byGOVDetalhado!D15 -> 0.43065653 | Y15: =[7]byGOVDetalhado!E15 -> 17.542154 | Z15: =[8]byGOVDetalhado!B15 -> 3.6589161 | AA15: =[8]byGOVDetalhado!C15 -> 0.1518569 | AB15: =[8]byGOVDetalhado!D15 -> 0.44107997 | AC15: =[8]byGOVDetalhado!E15 -> 19.531393 | AD15: =[9]byGOVDetalhado!B15 -> 4.0543466 | AE15: =[9]byGOVDetalhado!C15 -> 0.14904245 | AF15: =[9]byGOVDetalhado!D15 -> 0.43093778 | AG15: =[9]byGOVDetalhado!E15 -> 21.399175 | AH15: =[10]byGOVDetalhado!B15 -> 4.9633387 | AI15: =[10]byGOVDetalhado!C15 -> 0.15960299 | AJ15: =[10]byGOVDetalhado!D15 -> 0.45919174 | AK15: =[10]byGOVDetalhado!E15 -> 25.913828 | AL15: =[11]byGOVDetalhado!B15 -> 4.9891651 | AM15: =[11]byGOVDetalhado!C15 -> 0.14968817 | AN15: =[11]byGOVDetalhado!D15 -> 0.45135536 | AO15: =[11]byGOVDetalhado!E15 -> 25.777941 | AP15: =[12]byGOVDetalhado!B15 -> 5.9237249 | AQ15: =[12]byGOVDetalhado!C15 -> 0.1524436 | AR15: =[12]byGOVDetalhado!D15 -> 0.45871913 | AS15: =[12]byGOVDetalhado!E15 -> 30.300725 | AT15: =[13]byGOVDetalhado!B15 -> 7.1480912 | AU15: =[13]byGOVDetalhado!C15 -> 0.16333335 | AV15: =[13]byGOVDetalhado!D15 -> 0.4792218 | AW15: =[13]byGOVDetalhado!E15 -> 36.211749 | AX15: =[14]byGOVDetalhado!B15 -> 6.8505461 | AY15: =[14]byGOVDetalhado!C15 -> 0.14228219 | AZ15: =[14]byGOVDetalhado!D15 -> 0.41819788 | BA15: =[14]byGOVDetalhado!E15 -> 34.382963 | BB15: =[15]byGOVDetalhado!B15 -> 7.1480912 | BC15: =[15]byGOVDetalhado!C15 -> 0.13406981 | BD15: =[15]byGOVDetalhado!D15 -> 0.39883425 | BE15: =[15]byGOVDetalhado!E15 -> 35.556856 | BF15: =[16]byGOVDetalhado!B15 -> 6.8399028 | BG15: =[16]byGOVDetalhado!C15 -> 0.11835886 | BH15: =[16]byGOVDetalhado!D15 -> 0.36003633 | BI15: =[16]byGOVDetalhado!E15 -> 33.732561 | BJ15: =[17]byGOVDetalhado!B15 -> 7.369943 | BK15: =[17]byGOVDetalhado!C15 -> 0.12291869 | BL15: =[17]byGOVDetalhado!D15 -> 0.37429289 | BM15: =[17]byGOVDetalhado!E15 -> 36.04754 | BN15: =[18]byGOVDetalhado!B15 -> 8.5112539 | BO15: =[18]byGOVDetalhado!C15 -> 0.13580622 | BP15: =[18]byGOVDetalhado!D15 -> 0.40798732 | BQ15: =[18]byGOVDetalhado!E15 -> 41.30044 | BR15: =[19]byGOVDetalhado!B15 -> 8.3067015 | BS15: =[19]byGOVDetalhado!C15 -> 0.12674551 | BT15: =[19]byGOVDetalhado!D15 -> 0.37699395 | BU15: =[19]byGOVDetalhado!E15 -> 40.001273 | BV15: =[20]byGOVDetalhado!B15 -> 9.6090797 | BW15: =[20]byGOVDetalhado!C15 -> 0.13948082 | BX15: =[20]byGOVDetalhado!D15 -> 0.40496804 | BY15: =[20]byGOVDetalhado!E15 -> 46.08784 | BZ15: =[21]byGOVDetalhado!B15 -> 8.5844524 | CA15: =[21]byGOVDetalhado!C15 -> 0.11617675 | CB15: =[21]byGOVDetalhado!D15 -> 0.34380107 | CC15: =[21]byGOVDetalhado!E15 -> 40.849726 | CD15: =[22]byGOVDetalhado!B15 -> 6.1198764 | CE15: =[22]byGOVDetalhado!C15 -> 0.080423134 | CF15: =[22]byGOVDetalhado!D15 -> 0.2496322 | CG15: =[22]byGOVDetalhado!E15 -> 28.900647 | CH15: =[23]byGOVDetalhado!B15 -> 7.1798169 | CI15: =[23]byGOVDetalhado!C15 -> 0.08068364 | CJ15: =[23]byGOVDetalhado!D15 -> 0.23456052 | CK15: =[23]byGOVDetalhado!E15 -> 33.657868 | CL15: =[24]byGOVDetalhado!B15 -> 7.8124658 | CM15: =[24]byGOVDetalhado!C15 -> 0.077507113 | CN15: =[24]byGOVDetalhado!D15 -> 0.22203988 | CO15: =[24]byGOVDetalhado!E15 -> 38.46975 | CP15: =[25]byGOVDetalhado!B15 -> 8.9104359 | CQ15: =[25]byGOVDetalhado!C15 -> 0.081423337 | CR15: =[25]byGOVDetalhado!D15 -> 0.23547741 | CS15: =[25]byGOVDetalhado!E15 -> 42.87321 | CT15: =[26]byGOVDetalhado!B15 -> 9.4437154 | CU15: =[26]byGOVDetalhado!C15 -> 0.080408254 | CV15: =[26]byGOVDetalhado!D15 -> 0.22366696 | CW15: =[26]byGOVDetalhado!E15 -> 44.423506
A16: Previdência (1) | B16: =[2]byGOVDetalhado!B16 -> 55.712837 | C16: =[2]byGOVDetalhado!C16 -> 4.6335573 | D16: =[2]byGOVDetalhado!D16 -> 15.162219 | E16: =[2]byGOVDetalhado!E16 -> 321.20708 | F16: =[3]byGOVDetalhado!B16 -> 62.433582 | G16: =[3]byGOVDetalhado!C16 -> 4.7450765 | H16: =[3]byGOVDetalhado!D16 -> 14.807087 | I16: =[3]byGOVDetalhado!E16 -> 359.9549 | J16: =[4]byGOVDetalhado!B16 -> 69.251554 | K16: =[4]byGOVDetalhado!C16 -> 4.6515421 | L16: =[4]byGOVDetalhado!D16 -> 13.978217 | M16: =[4]byGOVDetalhado!E16 -> 388.45108 | N16: =[5]byGOVDetalhado!B16 -> 79.375176 | O16: =[5]byGOVDetalhado!C16 -> 4.6203426 | P16: =[5]byGOVDetalhado!D16 -> 14.173762 | Q16: =[5]byGOVDetalhado!E16 -> 439.46168 | R16: =[6]byGOVDetalhado!B16 -> 93.327546 | S16: =[6]byGOVDetalhado!C16 -> 4.7670795 | T16: =[6]byGOVDetalhado!D16 -> 14.178067 | U16: =[6]byGOVDetalhado!E16 -> 510.23338 | V16: =[7]byGOVDetalhado!B16 -> 106.6517 | W16: =[7]byGOVDetalhado!C16 -> 4.9135005 | X16: =[7]byGOVDetalhado!D16 -> 14.141332 | Y16: =[7]byGOVDetalhado!E16 -> 576.02614 | Z16: =[8]byGOVDetalhado!B16 -> 121.05943 | AA16: =[8]byGOVDetalhado!C16 -> 5.0243597 | AB16: =[8]byGOVDetalhado!D16 -> 14.593637 | AC16: =[8]byGOVDetalhado!E16 -> 646.21852 | AD16: =[9]byGOVDetalhado!B16 -> 138.11807 | AE16: =[9]byGOVDetalhado!C16 -> 5.0773794 | AF16: =[9]byGOVDetalhado!D16 -> 14.680614 | AG16: =[9]byGOVDetalhado!E16 -> 728.99855 | AH16: =[10]byGOVDetalhado!B16 -> 158.09568 | AI16: =[10]byGOVDetalhado!C16 -> 5.0837844 | AJ16: =[10]byGOVDetalhado!D16 -> 14.626491 | AK16: =[10]byGOVDetalhado!E16 -> 825.42509 | AL16: =[11]byGOVDetalhado!B16 -> 178.24284 | AM16: =[11]byGOVDetalhado!C16 -> 5.3477574 | AN16: =[11]byGOVDetalhado!D16 -> 16.125115 | AO16: =[11]byGOVDetalhado!E16 -> 920.94237 | AP16: =[12]byGOVDetalhado!B16 -> 210.4037 | AQ16: =[12]byGOVDetalhado!C16 -> 5.4146161 | AR16: =[12]byGOVDetalhado!D16 -> 16.293161 | AS16: =[12]byGOVDetalhado!E16 -> 1076.2459 | AT16: =[13]byGOVDetalhado!B16 -> 242.23414 | AU16: =[13]byGOVDetalhado!C16 -> 5.5350319 | AV16: =[13]byGOVDetalhado!D16 -> 16.239843 | AW16: =[13]byGOVDetalhado!E16 -> 1227.1418 | AX16: =[14]byGOVDetalhado!B16 -> 269.00561 | AY16: =[14]byGOVDetalhado!C16 -> 5.5871033 | AZ16: =[14]byGOVDetalhado!D16 -> 16.421695 | BA16: =[14]byGOVDetalhado!E16 -> 1350.142 | BB16: =[15]byGOVDetalhado!B16 -> 292.7361 | BC16: =[15]byGOVDetalhado!C16 -> 5.4905668 | BD16: =[15]byGOVDetalhado!D16 -> 16.333477 | BE16: =[15]byGOVDetalhado!E16 -> 1456.1615 | BF16: =[16]byGOVDetalhado!B16 -> 312.81126 | BG16: =[16]byGOVDetalhado!C16 -> 5.4129401 | BH16: =[16]byGOVDetalhado!D16 -> 16.465646 | BI16: =[16]byGOVDetalhado!E16 -> 1542.701 | BJ16: =[17]byGOVDetalhado!B16 -> 315.94696 | BK16: =[17]byGOVDetalhado!C16 -> 5.2694828 | BL16: =[17]byGOVDetalhado!D16 -> 16.04581 | BM16: =[17]byGOVDetalhado!E16 -> 1545.3459 | BN16: =[18]byGOVDetalhado!B16 -> 333.76555 | BO16: =[18]byGOVDetalhado!C16 -> 5.3255886 | BP16: =[18]byGOVDetalhado!D16 -> 15.999066 | BQ16: =[18]byGOVDetalhado!E16 -> 1619.5809 | BR16: =[19]byGOVDetalhado!B16 -> 351.88658 | BS16: =[19]byGOVDetalhado!C16 -> 5.3691643 | BT16: =[19]byGOVDetalhado!D16 -> 15.970131 | BU16: =[19]byGOVDetalhado!E16 -> 1694.5247 | BV16: =[20]byGOVDetalhado!B16 -> 371.2967 | BW16: =[20]byGOVDetalhado!C16 -> 5.3895661 | BX16: =[20]byGOVDetalhado!D16 -> 15.648043 | BY16: =[20]byGOVDetalhado!E16 -> 1780.8431 | BZ16: =[21]byGOVDetalhado!B16 -> 394.94103 | CA16: =[21]byGOVDetalhado!C16 -> 5.3448914 | CB16: =[21]byGOVDetalhado!D16 -> 15.817101 | CC16: =[21]byGOVDetalhado!E16 -> 1879.3549 | CD16: =[22]byGOVDetalhado!B16 -> 386.78782 | CE16: =[22]byGOVDetalhado!C16 -> 5.0828949 | CF16: =[22]byGOVDetalhado!D16 -> 15.777229 | CG16: =[22]byGOVDetalhado!E16 -> 1826.5758 | CH16: =[23]byGOVDetalhado!B16 -> 443.13288 | CI16: =[23]byGOVDetalhado!C16 -> 4.9797333 | CJ16: =[23]byGOVDetalhado!D16 -> 14.476898 | CK16: =[23]byGOVDetalhado!E16 -> 2077.3382 | CL16: =[24]byGOVDetalhado!B16 -> 514.64479 | CM16: =[24]byGOVDetalhado!C16 -> 5.1057672 | CN16: =[24]byGOVDetalhado!D16 -> 14.626838 | CO16: =[24]byGOVDetalhado!E16 -> 2534.1879 | CP16: =[25]byGOVDetalhado!B16 -> 534.84268 | CQ16: =[25]byGOVDetalhado!C16 -> 4.8873788 | CR16: =[25]byGOVDetalhado!D16 -> 14.134367 | CS16: =[25]byGOVDetalhado!E16 -> 2573.4344 | CT16: =[26]byGOVDetalhado!B16 -> 611.64221 | CU16: =[26]byGOVDetalhado!C16 -> 5.2078107 | CV16: =[26]byGOVDetalhado!D16 -> 14.486264 | CW16: =[26]byGOVDetalhado!E16 -> 2877.1823
A17: Cofins | B17: =[2]byGOVDetalhado!B17 -> 38.634039 | C17: =[2]byGOVDetalhado!C17 -> 3.213138 | D17: =[2]byGOVDetalhado!D17 -> 10.514233 | E17: =[2]byGOVDetalhado!E17 -> 222.74089 | F17: =[3]byGOVDetalhado!B17 -> 45.678823 | G17: =[3]byGOVDetalhado!C17 -> 3.4716815 | H17: =[3]byGOVDetalhado!D17 -> 10.833437 | I17: =[3]byGOVDetalhado!E17 -> 263.35693 | J17: =[4]byGOVDetalhado!B17 -> 50.855606 | K17: =[4]byGOVDetalhado!C17 -> 3.4159088 | L17: =[4]byGOVDetalhado!D17 -> 10.26505 | M17: =[4]byGOVDetalhado!E17 -> 285.26313 | N17: =[5]byGOVDetalhado!B17 -> 57.522166 | O17: =[5]byGOVDetalhado!C17 -> 3.3483027 | P17: =[5]byGOVDetalhado!D17 -> 10.271543 | Q17: =[5]byGOVDetalhado!E17 -> 318.47221 | R17: =[6]byGOVDetalhado!B17 -> 77.290069 | S17: =[6]byGOVDetalhado!C17 -> 3.9479009 | T17: =[6]byGOVDetalhado!D17 -> 11.741697 | U17: =[6]byGOVDetalhado!E17 -> 422.55448 | V17: =[7]byGOVDetalhado!B17 -> 86.532235 | W17: =[7]byGOVDetalhado!C17 -> 3.9865859 | X17: =[7]byGOVDetalhado!D17 -> 11.473619 | Y17: =[7]byGOVDetalhado!E17 -> 467.36083 | Z17: =[8]byGOVDetalhado!B17 -> 89.096351 | AA17: =[8]byGOVDetalhado!C17 -> 3.6977879 | AB17: =[8]byGOVDetalhado!D17 -> 10.740507 | AC17: =[8]byGOVDetalhado!E17 -> 475.59872 | AD17: =[9]byGOVDetalhado!B17 -> 100.55555 | AE17: =[9]byGOVDetalhado!C17 -> 3.6965379 | AF17: =[9]byGOVDetalhado!D17 -> 10.688081 | AG17: =[9]byGOVDetalhado!E17 -> 530.74047 | AH17: =[10]byGOVDetalhado!B17 -> 118.43105 | AI17: =[10]byGOVDetalhado!C17 -> 3.8083136 | AJ17: =[10]byGOVDetalhado!D17 -> 10.95685 | AK17: =[10]byGOVDetalhado!E17 -> 618.33416 | AL17: =[11]byGOVDetalhado!B17 -> 114.72393 | AM17: =[11]byGOVDetalhado!C17 -> 3.4420219 | AN17: =[11]byGOVDetalhado!D17 -> 10.378743 | AO17: =[11]byGOVDetalhado!E17 -> 592.75385 | AP17: =[12]byGOVDetalhado!B17 -> 138.636 | AQ17: =[12]byGOVDetalhado!C17 -> 3.5677165 | AR17: =[12]byGOVDetalhado!D17 -> 10.735641 | AS17: =[12]byGOVDetalhado!E17 -> 709.14356 | AT17: =[13]byGOVDetalhado!B17 -> 158.16676 | AU17: =[13]byGOVDetalhado!C17 -> 3.6140987 | AV17: =[13]byGOVDetalhado!D17 -> 10.603804 | AW17: =[13]byGOVDetalhado!E17 -> 801.26218 | AX17: =[14]byGOVDetalhado!B17 -> 174.626 | AY17: =[14]byGOVDetalhado!C17 -> 3.6268889 | AZ17: =[14]byGOVDetalhado!D17 -> 10.660204 | BA17: =[14]byGOVDetalhado!E17 -> 876.44971 | BB17: =[15]byGOVDetalhado!B17 -> 193.12483 | BC17: =[15]byGOVDetalhado!C17 -> 3.6222548 | BD17: =[15]byGOVDetalhado!D17 -> 10.775575 | BE17: =[15]byGOVDetalhado!E17 -> 960.66368 | BF17: =[16]byGOVDetalhado!B17 -> 193.55241 | BG17: =[16]byGOVDetalhado!C17 -> 3.3492643 | BH17: =[16]byGOVDetalhado!D17 -> 10.188142 | BI17: =[16]byGOVDetalhado!E17 -> 954.54841 | BJ17: =[17]byGOVDetalhado!B17 -> 199.3447 | BK17: =[17]byGOVDetalhado!C17 -> 3.3247462 | BL17: =[17]byGOVDetalhado!D17 -> 10.124 | BM17: =[17]byGOVDetalhado!E17 -> 975.02602 | BN17: =[18]byGOVDetalhado!B17 -> 200.94415 | BO17: =[18]byGOVDetalhado!C17 -> 3.2062801 | BP17: =[18]byGOVDetalhado!D17 -> 9.6322663 | BQ17: =[18]byGOVDetalhado!E17 -> 975.07158 | BR17: =[19]byGOVDetalhado!B17 -> 214.80578 | BS17: =[19]byGOVDetalhado!C17 -> 3.2775547 | BT17: =[19]byGOVDetalhado!D17 -> 9.7488129 | BU17: =[19]byGOVDetalhado!E17 -> 1034.4063 | BV17: =[20]byGOVDetalhado!B17 -> 243.26353 | BW17: =[20]byGOVDetalhado!C17 -> 3.5310976 | BX17: =[20]byGOVDetalhado!D17 -> 10.252174 | BY17: =[20]byGOVDetalhado!E17 -> 1166.7601 | BZ17: =[21]byGOVDetalhado!B17 -> 236.27309 | CA17: =[21]byGOVDetalhado!C17 -> 3.1975761 | CB17: =[21]byGOVDetalhado!D17 -> 9.4625652 | CC17: =[21]byGOVDetalhado!E17 -> 1124.3223 | CD17: =[22]byGOVDetalhado!B17 -> 217.3663 | CE17: =[22]byGOVDetalhado!C17 -> 2.8564759 | CF17: =[22]byGOVDetalhado!D17 -> 8.8664581 | CG17: =[22]byGOVDetalhado!E17 -> 1026.4957 | CH17: =[23]byGOVDetalhado!B17 -> 267.76451 | CI17: =[23]byGOVDetalhado!C17 -> 3.0090204 | CJ17: =[23]byGOVDetalhado!D17 -> 8.7477138 | CK17: =[23]byGOVDetalhado!E17 -> 1255.2385 | CL17: =[24]byGOVDetalhado!B17 -> 269.29528 | CM17: =[24]byGOVDetalhado!C17 -> 2.671666 | CN17: =[24]byGOVDetalhado!D17 -> 7.653703 | CO17: =[24]byGOVDetalhado!E17 -> 1326.0502 | CP17: =[25]byGOVDetalhado!B17 -> 326.94474 | CQ17: =[25]byGOVDetalhado!C17 -> 2.9876127 | CR17: =[25]byGOVDetalhado!D17 -> 8.6402171 | CS17: =[25]byGOVDetalhado!E17 -> 1573.1184 | CT17: =[26]byGOVDetalhado!B17 -> 353.79252 | CU17: =[26]byGOVDetalhado!C17 -> 3.0123567 | CV17: =[26]byGOVDetalhado!D17 -> 8.3792971 | CW17: =[26]byGOVDetalhado!E17 -> 1664.2501
