Workbook
Name \0: [1]DIRIND!$U$1
Name \a: #N/A
Name RECADM: #N/A

Sheet byGOVDetalhado
A1: Arrecadação Direta por Esfera de Governo: 2024
A3: Esfera de Governo | B3: 2024
B4: R$ Bilhões | C4: % PIB | D4: % Total | E4: Per capita (R$)
A5: PIB | B5: 11744.709
A6: POPULAÇÃO | B6: 212583750
A7: TOTAL | B7: =+B9+B29+B39 -> 4222.222 | C7: =+C9+C29+C39 -> 35.949992 | D7: =+D9+D29+D39 -> 100 | E7: =(B7*1000000000)/$B$6 -> 19861.452
A9: UNIÃO | B9: =SUM(B10:B27) -> 2735.2139 | C9: =SUM(C10:C27) -> 23.288903 | D9: =SUM(D10:D27) -> 64.781386 | E9: =(B9*1000000000)/$B$6 -> 12866.524
A10: IR | B10: =Impostos!D19+Impostos!D24+Impostos!D29+SUM(Impostos!D33:D35) -> 764.55033 | C10: =+B10/B$5*100 -> 6.5097427 | D10: =+C10/C$7*100 -> 18.107772 | E10: =(B10*1000000000)/$B$6 -> 3596.4665 | F10: Balanço Geral da União (STN)
A11: IPI | B11: =Impostos!D37+SUM(Impostos!D39:D41)+Impostos!D43 -> 82.173979 | C11: =+B11/B$5*100 -> 0.69966807 | D11: =+C11/C$7*100 -> 1.9462259 | E11: =(B11*1000000000)/$B$6 -> 386.54873 | F11: Balanço Geral da União (STN)
A12: IOF | B12: =Impostos!D48+Impostos!D50 -> 67.40223 | C12: =+B12/B$5*100 -> 0.57389442 | D12: =+C12/C$7*100 -> 1.5963687 | E12: =(B12*1000000000)/$B$6 -> 317.062 | F12: Balanço Geral da União (STN)
A13: Imp. Sobre Comércio Exterior | B13: =Impostos!D2+Impostos!D7 -> 77.507333 | C13: =+B13/B$5*100 -> 0.65993405 | D13: =+C13/C$7*100 -> 1.8357001 | E13: =(B13*1000000000)/$B$6 -> 364.5967 | F13: Balanço Geral da União (STN)
A14: ITR | B14: =Impostos!D12+Impostos!D14 -> 3.2455194 | C14: =+B14/B$5*100 -> 0.027633885 | D14: =+C14/C$7*100 -> 0.076867569 | E14: =(B14*1000000000)/$B$6 -> 15.267016 | F14: Balanço Geral da União (STN)
A15: Taxas | B15: =Impostos!D59 -> 9.4437154 | C15: =+B15/B$5*100 -> 0.080408254 | D15: =+C15/C$7*100 -> 0.22366696 | E15: =(B15*1000000000)/$B$6 -> 44.423506 | F15: Balanço Geral da União (STN)
A16: Previdência (1) | B16: =SUM(Contribuições!D149:D152) -> 611.64221 | C16: =+B16/B$5*100 -> 5.2078107 | D16: =+C16/C$7*100 -> 14.486264 | E16: =(B16*1000000000)/$B$6 -> 2877.1823 | F16: Balanço Geral da União (STN)
A17: Cofins | B17: =SUM(Contribuições!D7:D9) -> 353.79252 | C17: =+B17/B$5*100 -> 3.0123567 | D17: =+C17/C$7*100 -> 8.3792971 | E17: =(B17*1000000000)/$B$6 -> 1664.2501 | F17: Balanço Geral da União (STN)
A18: CPMF | B18: =Contribuições!D10 -> -0.022443285 | C18: =+B18/B$5*100 -> -0.00019109273 | D18: =+C18/C$7*100 -> -0.00053155152 | E18: =(B18*1000000000)/$B$6 -> -0.10557385 | F18: Balanço Geral da União (STN)
A19: CSLL | B19: =SUM(Contribuições!D11:D13) -> 160.6067 | C19: =+B19/B$5*100 -> 1.3674813 | D19: =+C19/C$7*100 -> 3.8038431 | E19: =(B19*1000000000)/$B$6 -> 755.49848 | F19: Balanço Geral da União (STN)
A20: PIS-PASEP | B20: =SUM(Contribuições!D146:D148) -> 99.843386 | C20: =+B20/B$5*100 -> 0.85011375 | D20: =+C20/C$7*100 -> 2.3647119 | E20: =(B20*1000000000)/$B$6 -> 469.66613 | F20: Balanço Geral da União (STN)
A21: Contrib. Seg. Serv. Público (2) | B21: =SUM(Contribuições!D153:D161) -> 28.419425 | C21: =+B21/B$5*100 -> 0.2419764 | D21: =+C21/C$7*100 -> 0.67309167 | E21: =(B21*1000000000)/$B$6 -> 133.68578 | F21: Balanço Geral da União (STN)
A22: Outras contribuições sociais (3) | B22: =SUM(Contribuições!D14:D21,Contribuições!D141:D144,Contribuições!D165:D169)+Multas!D2 -> 6.784134 | C22: =+B22/B$5*100 -> 0.057763321 | D22: =+C22/C$7*100 -> 0.16067687 | E22: =(B22*1000000000)/$B$6 -> 31.912759 | F22: Balanço Geral da União (STN)
A23: FGTS | B23: 191.995 | C23: =+B23/B$5*100 -> 1.6347361 | D23: =+C23/C$7*100 -> 4.5472503 | E23: =(B23*1000000000)/$B$6 -> 903.14994 | F23: CEF
A24: Contribuições Econômicas (4) | B24: =SUM(Contribuições!D2:D6,Contribuições!D139:D140,Contribuições!D145,Contribuições!D164,Contribuições!D170:D174)+SUM(Patrimoniais!D2:D15,Patrimoniais!D17:D18,Patrimoniais!D21) -> 138.96569 | C24: =+B24/B$5*100 -> 1.1832195 | D24: =+C24/C$7*100 -> 3.2912927 | E24: =(B24*1000000000)/$B$6 -> 653.69854 | F24: Balanço Geral da União (STN)
A25: Salário Educação | B25: =SUM(Contribuições!D162:D163) -> 32.120722 | C25: =+B25/B$5*100 -> 0.27349099 | D25: =+C25/C$7*100 -> 0.76075397 | E25: =(B25*1000000000)/$B$6 -> 151.09679 | F25: Balanço Geral da União (STN)
A26: Sistema S | B26: 29.319759 | C26: =+B26/B$5*100 -> 0.24964227 | D26: =+C26/C$7*100 -> 0.69441538 | E26: =(B26*1000000000)/$B$6 -> 137.92098 | F26: RFB
A27: Multas e Dívida Ativa | B27: =Contribuições!D175+Impostos!D91+Patrimoniais!D24 -> 77.423706 | C27: =+B27/B$5*100 -> 0.659222 | D27: =+C27/C$7*100 -> 1.8337194 | E27: =(B27*1000000000)/$B$6 -> 364.20331 | F27: Balanço Geral da União (STN)
A29: ESTADOS | B29: =SUM(B30:B37) -> 1127.2114 | C29: =SUM(C30:C37) -> 9.5976102 | D29: =SUM(D30:D37) -> 26.697113 | E29: =(B29*1000000000)/$B$6 -> 5302.4344
A30: ICMS | B30: =Estados!B2 -> 828.14597 | C30: =+B30/B$5*100 -> 7.0512259 | D30: =+C30/C$7*100 -> 19.613985 | E30: =(B30*1000000000)/$B$6 -> 3895.6222 | F30: Finbra (Siconfi/STN)
A31: IPVA | B31: =Estados!B3 -> 87.533122 | C31: =+B31/B$5*100 -> 0.74529834 | D31: =+C31/C$7*100 -> 2.073153 | E31: =(B31*1000000000)/$B$6 -> 411.75829 | F31: Finbra (Siconfi/STN)
A32: ITCD | B32: =Estados!B4 -> 18.575221 | C32: =+B32/B$5*100 -> 0.1581582 | D32: =+C32/C$7*100 -> 0.43993946 | E32: =(B32*1000000000)/$B$6 -> 87.378365 | F32: Finbra (Siconfi/STN)
A33: IRRF | B33: =Estados!B5 -> 81.090062 | C33: =+B33/B$5*100 -> 0.69043909 | D33: =+C33/C$7*100 -> 1.9205542 | E33: =(B33*1000000000)/$B$6 -> 381.44995 | F33: Finbra (Siconfi/STN)
A34: TAXAS | B34: =Estados!B6 -> 48.769144 | C34: =+B34/B$5*100 -> 0.41524353 | D34: =+C34/C$7*100 -> 1.1550587 | E34: =(B34*1000000000)/$B$6 -> 229.41144 | F34: Finbra (Siconfi/STN)
A35: Previ. Estadual | B35: =Estados!B7 -> 55.32654 | C35: =+B35/B$5*100 -> 0.4710763 | D35: =+C35/C$7*100 -> 1.3103655 | E35: =(B35*1000000000)/$B$6 -> 260.25762 | F35: Finbra (Siconfi/STN)
A36: Contribuições de Melhoria e Econômicas | B36: =Estados!B8 -> 7.7713305 | C36: =+B36/B$5*100 -> 0.066168779 | D36: =+C36/C$7*100 -> 0.18405784 | E36: =(B36*1000000000)/$B$6 -> 36.55656 | F36: Finbra (Siconfi/STN)
A37: Demais (multas, juros e dívida ativa) | B37: =Estados!B9 -> 0 | C37: =+B37/B$5*100 -> 0 | D37: =+C37/C$7*100 -> 0 | E37: =(B37*1000000000)/$B$6 -> 0 | F37: Finbra (Siconfi/STN)
A39: MUNICÍPIOS | B39: =SUM(B40:B47) -> 359.79669 | C39: =SUM(C40:C47) -> 3.0634789 | D39: =SUM(D40:D47) -> 8.521501 | E39: =(B39*1000000000)/$B$6 -> 1692.4938
A40: ISS | B40: =Municipios!E2+Estados!B10 -> 142.63379 | C40: =+B40/B$5*100 -> 1.2144515 | D40: =+C40/C$7*100 -> 3.378169 | E40: =(B40*1000000000)/$B$6 -> 670.95341 | F40: Finbra (Siconfi/STN)
A41: IPTU | B41: =Municipios!C2+Estados!B11 -> 77.634384 | C41: =+B41/B$5*100 -> 0.66101581 | D41: =+C41/C$7*100 -> 1.8387092 | E41: =(B41*1000000000)/$B$6 -> 365.19435 | F41: Finbra (Siconfi/STN)
A42: ITBI | B42: =Municipios!D2+Estados!B12 -> 25.102512 | C42: =+B42/B$5*100 -> 0.21373464 | D42: =+C42/C$7*100 -> 0.5945332 | E42: =(B42*1000000000)/$B$6 -> 118.08293 | F42: Finbra (Siconfi/STN)
A43: IRRF | B43: =Municipios!B2 -> 48.838753 | C43: =+B43/B$5*100 -> 0.41583622 | D43: =+C43/C$7*100 -> 1.1567074 | E43: =(B43*1000000000)/$B$6 -> 229.73888 | F43: Finbra (Siconfi/STN)
A44: TAXAS | B44: =Municipios!F2 -> 20.125118 | C44: =+B44/B$5*100 -> 0.17135476 | D44: =+C44/C$7*100 -> 0.47664755 | E44: =(B44*1000000000)/$B$6 -> 94.669126 | F44: Finbra (Siconfi/STN)
...

Sheet AD ESFERA
A1: Arrecadação Direta por Esfera de Governo: 2024
A3: Esfera de Governo | B3: =byGOVDetalhado!B3 -> 2024
B4: R$ Bilhões | C4: % PIB | D4: % Total | E4: Per capita (R$)
A5: PIB | B5: =byGOVDetalhado!B5 -> 11744.709
A6: POPULAÇÃO | B6: =byGOVDetalhado!B6 -> 212583750
A7: TOTAL | B7: =+B9+B16+B21 -> 4222.222 | C7: =+C9+C16+C21 -> 35.949992 | D7: =+D9+D16+D21 -> 100 | E7: =(B7*1000000000)/$B$6 -> 19861.452
E8: =(B8*1000000000)/$B$6 -> 0
A9: UNIÃO | B9: =SUM(B10:B14) -> 2735.2139 | C9: =SUM(C10:C14) -> 23.288903 | D9: =SUM(D10:D14) -> 64.781386 | E9: =(B9*1000000000)/$B$6 -> 12866.524 | I9: Setor Público | J9: União
A10: Impostos | B10: =+SUM(byGOVDetalhado!B10:B14) -> 994.87939 | C10: =+B10/B$5*100 -> 8.4708731 | D10: =+C10/C$7*100 -> 23.562934 | E10: =(B10*1000000000)/$B$6 -> 4679.9409 | H10: Impostos | I10: =C10+C17+C18+C22+C23+byGOVDetalhado!C32+byGOVDetalhado!C33+byGOVDetalhado!C42+byGOVDetalhado!C43 -> 19.621033 | J10: =C10 -> 8.4708731
A11: Contribuições Sociais | B11: =SUM(byGOVDetalhado!B17:B22,byGOVDetalhado!B25:B26) -> 710.86421 | C11: =+B11/B$5*100 -> 6.0526336 | D11: =+C11/C$7*100 -> 16.836258 | E11: =(B11*1000000000)/$B$6 -> 3343.9254 | H11: Contribuições | I11: =C11+C12+C13+byGOVDetalhado!C35+byGOVDetalhado!C36+byGOVDetalhado!C45+byGOVDetalhado!C46+byGOVDetalhado!C24 -> 15.002731 | J11: =C11+byGOVDetalhado!C24+'AD ESFERA'!C12+'AD ESFERA'!C13 -> 14.0784
A12: Previdência Social | B12: =+byGOVDetalhado!B16 -> 611.64221 | C12: =+B12/B$5*100 -> 5.2078107 | D12: =+C12/C$7*100 -> 14.486264 | E12: =(B12*1000000000)/$B$6 -> 2877.1823 | H12: Taxas | I12: =byGOVDetalhado!C15+byGOVDetalhado!C34+byGOVDetalhado!C44 -> 0.66700654 | J12: =byGOVDetalhado!C15 -> 0.080408254
A13: FGTS | B13: =+byGOVDetalhado!B23 -> 191.995 | C13: =+B13/B$5*100 -> 1.6347361 | D13: =+C13/C$7*100 -> 4.5472503 | E13: =(B13*1000000000)/$B$6 -> 903.14994 | H13: Outros | I13: =I14-SUM(I10:I12) -> 0.659222 | J13: =J14-SUM(J10:J12) -> 0.659222
A14: Demais | B14: =+SUM(byGOVDetalhado!B15,byGOVDetalhado!B24,byGOVDetalhado!B27) -> 225.83311 | C14: =+B14/B$5*100 -> 1.9228497 | D14: =+C14/C$7*100 -> 5.3486791 | E14: =(B14*1000000000)/$B$6 -> 1062.3254 | I14: =C7 -> 35.949992 | J14: =C9 -> 23.288903
E15: =(B15*1000000000)/$B$6 -> 0
A16: ESTADOS | B16: =SUM(B17:B20) -> 1127.2114 | C16: =SUM(C17:C20) -> 9.5976102 | D16: =SUM(D17:D20) -> 26.697113 | E16: =(B16*1000000000)/$B$6 -> 5302.4344
A17: ICMS | B17: =+byGOVDetalhado!B30 -> 828.14597 | C17: =+B17/B$5*100 -> 7.0512259 | D17: =+C17/C$7*100 -> 19.613985 | E17: =(B17*1000000000)/$B$6 -> 3895.6222
A18: IPVA | B18: =+byGOVDetalhado!B31 -> 87.533122 | C18: =+B18/B$5*100 -> 0.74529834 | D18: =+C18/C$7*100 -> 2.073153 | E18: =(B18*1000000000)/$B$6 -> 411.75829
A19: Demais | B19: =+SUM(byGOVDetalhado!B32:B37) -> 211.5323 | C19: =+B19/B$5*100 -> 1.8010859 | D19: =+C19/C$7*100 -> 5.0099757 | E19: =(B19*1000000000)/$B$6 -> 995.05393
E20: =(B20*1000000000)/$B$6 -> 0
A21: MUNICÍPIOS | B21: =SUM(B22:B24) -> 359.79669 | C21: =SUM(C22:C24) -> 3.0634789 | D21: =SUM(D22:D24) -> 8.521501 | E21: =(B21*1000000000)/$B$6 -> 1692.4938
A22: ISS | B22: =+byGOVDetalhado!B40 -> 142.63379 | C22: =+B22/B$5*100 -> 1.2144515 | D22: =+C22/C$7*100 -> 3.378169 | E22: =(B22*1000000000)/$B$6 -> 670.95341
A23: IPTU | B23: =+byGOVDetalhado!B41 -> 77.634384 | C23: =+B23/B$5*100 -> 0.66101581 | D23: =+C23/C$7*100 -> 1.8387092 | E23: =(B23*1000000000)/$B$6 -> 365.19435
A24: Demais | B24: =+SUM(byGOVDetalhado!B42:B47) -> 139.52851 | C24: =+B24/B$5*100 -> 1.1880116 | D24: =+C24/C$7*100 -> 3.3046228 | E24: =(B24*1000000000)/$B$6 -> 656.34608
A25: Fonte: Elaboração Própria (Balanço Oficial da União, STN; Balanço dos Estados, STN; Finbra, STN; SRF)

Sheet PRINCIPAIS TRIBUTOS
A1: Arrecadação Tributária por Principais Impostos e Contribuições: 2024
A3: Principais Tributos | B3: =byGOVDetalhado!B3 -> 2024
B4: R$ Bilhões | C4: % PIB | D4: % Total | E4: Per capita (R$)
A5: PIB | B5: =byGOVDetalhado!B5 -> 11744.709
A6: POPULAÇÃO | B6: =byGOVDetalhado!B6 -> 212583750
A7: TOTAL | B7: ='AD ESFERA'!B7 -> 4222.222 | C7: =B7/B5*100 -> 35.949992 | D7: =SUM(D9:D26) -> 99.999468 | E7: =(B7*1000000000)/$B$6 -> 19861.452
E8: =(B8*1000000000)/$B$6 -> 0
A9: ICMS | B9: =byGOVDetalhado!B30 -> 828.14597 | C9: =+B9/B$5*100 -> 7.0512259 | D9: =+C9/C$7*100 -> 19.613985 | E9: =(B9*1000000000)/$B$6 -> 3895.6222 | F9: =C9 -> 7.0512259 | G9: =D9 -> 19.613985 | I9: ICMS | J9: =D9 -> 19.613985
A10: Previdência Social Ampliada (1) | B10: =byGOVDetalhado!B16+byGOVDetalhado!B25+byGOVDetalhado!B26 -> 673.08269 | C10: =+B10/B$5*100 -> 5.7309439 | D10: =+C10/C$7*100 -> 15.941433 | E10: =(B10*1000000000)/$B$6 -> 3166.2001 | F10: =F9+C10 -> 12.78217 | G10: =G9+D10 -> 35.555418 | I10: IR + CSLL | J10: =D11+D15 -> 24.988877
A11: Imposto de Renda (Global) | B11: =byGOVDetalhado!B10+byGOVDetalhado!B33+byGOVDetalhado!B43 -> 894.47915 | C11: =+B11/B$5*100 -> 7.616018 | D11: =+C11/C$7*100 -> 21.185034 | E11: =(B11*1000000000)/$B$6 -> 4207.6553 | F11: =F10+C11 -> 20.398188 | G11: =G10+D11 -> 56.740451 | I11: Prev + FGTS | J11: =D10+D13 -> 20.488683
A12: Cofins | B12: =byGOVDetalhado!B17 -> 353.79252 | C12: =+B12/B$5*100 -> 3.0123567 | D12: =+C12/C$7*100 -> 8.3792971 | E12: =(B12*1000000000)/$B$6 -> 1664.2501 | F12: =F11+C12 -> 23.410545 | G12: =G11+D12 -> 65.119748 | I12: Cofins + PIS | J12: =D12+D16 -> 10.744009
A13: FGTS | B13: =byGOVDetalhado!B23 -> 191.995 | C13: =+B13/B$5*100 -> 1.6347361 | D13: =+C13/C$7*100 -> 4.5472503 | E13: =(B13*1000000000)/$B$6 -> 903.14994 | F13: =F12+C13 -> 25.045281 | G13: =G12+D13 -> 69.666998 | I13: ISS | J13: =D17 -> 3.378169
A14: IPI | B14: =byGOVDetalhado!B11 -> 82.173979 | C14: =+B14/B$5*100 -> 0.69966807 | D14: =+C14/C$7*100 -> 1.9462259 | E14: =(B14*1000000000)/$B$6 -> 386.54873 | F14: =F13+C14 -> 25.744949 | G14: =G13+D14 -> 71.613224 | I14: Outros | J14: =SUM(D14,D18:D26) -> 20.785746
A15: Contrib. Lucro | B15: =byGOVDetalhado!B19 -> 160.6067 | C15: =+B15/B$5*100 -> 1.3674813 | D15: =+C15/C$7*100 -> 3.8038431 | E15: =(B15*1000000000)/$B$6 -> 755.49848 | F15: =F14+C15 -> 27.11243 | G15: =G14+D15 -> 75.417067
A16: Pis/Pasep | B16: =byGOVDetalhado!B20 -> 99.843386 | C16: =+B16/B$5*100 -> 0.85011375 | D16: =+C16/C$7*100 -> 2.3647119 | E16: =(B16*1000000000)/$B$6 -> 469.66613 | F16: =F15+C16 -> 27.962544 | G16: =G15+D16 -> 77.781779
A17: ISS | B17: =byGOVDetalhado!B40 -> 142.63379 | C17: =+B17/B$5*100 -> 1.2144515 | D17: =+C17/C$7*100 -> 3.378169 | E17: =(B17*1000000000)/$B$6 -> 670.95341 | F17: =F16+C17 -> 29.176995 | G17: =G16+D17 -> 81.159948
A18: Imp. Importação | B18: =byGOVDetalhado!B13 -> 77.507333 | C18: =+B18/B$5*100 -> 0.65993405 | D18: =+C18/C$7*100 -> 1.8357001 | E18: =(B18*1000000000)/$B$6 -> 364.5967 | F18: =F17+C18 -> 29.836929 | G18: =G17+D18 -> 82.995648
A19: IPVA | B19: =byGOVDetalhado!B31 -> 87.533122 | C19: =+B19/B$5*100 -> 0.74529834 | D19: =+C19/C$7*100 -> 2.073153 | E19: =(B19*1000000000)/$B$6 -> 411.75829
A20: IPTU | B20: =byGOVDetalhado!B41 -> 77.634384 | C20: =+B20/B$5*100 -> 0.66101581 | D20: =+C20/C$7*100 -> 1.8387092 | E20: =(B20*1000000000)/$B$6 -> 365.19435
A21: IOF | B21: =byGOVDetalhado!B12 -> 67.40223 | C21: =+B21/B$5*100 -> 0.57389442 | D21: =+C21/C$7*100 -> 1.5963687 | E21: =(B21*1000000000)/$B$6 -> 317.062
A22: ITBI | B22: =byGOVDetalhado!B42 -> 25.102512 | C22: =+B22/B$5*100 -> 0.21373464 | D22: =+C22/C$7*100 -> 0.5945332 | E22: =(B22*1000000000)/$B$6 -> 118.08293
A23: ITCD | B23: =byGOVDetalhado!B32 -> 18.575221 | C23: =+B23/B$5*100 -> 0.1581582 | D23: =+C23/C$7*100 -> 0.43993946 | E23: =(B23*1000000000)/$B$6 -> 87.378365
A24: ITR | B24: =byGOVDetalhado!B14 -> 3.2455194 | C24: =+B24/B$5*100 -> 0.027633885 | D24: =+C24/C$7*100 -> 0.076867569 | E24: =(B24*1000000000)/$B$6 -> 15.267016
A25: CPMF | B25: =byGOVDetalhado!B18 -> -0.022443285 | C25: =+B25/B$5*100 -> -0.00019109273 | D25: =+C25/C$7*100 -> -0.00053155152 | E25: =(B25*1000000000)/$B$6 -> -0.10557385
A26: Demais tributos | B26: =B7-SUM(B9:B24) -> 438.46848 | C26: =+B26/B$5*100 -> 3.7333278 | D26: =+C26/C$7*100 -> 10.38478 | E26: =(B26*1000000000)/$B$6 -> 2062.5682
A27: Fonte: Elaboração Própria (Balanço Oficial da União, STN; Balanço dos Estados, STN; Finbra, STN; SRF)
A28: (1) Inclui Sistema "S" e Salário Educação

Sheet Bases de Incidência
A1: Arrecadação por Bases de Incidência: 2024
A3: Base de Incidência | B3: =byGOVDetalhado!B3 -> 2024
B4: R$ Bilhões | C4: % PIB | D4: % Total | E4: Per capita (R$)
A5: PIB | B5: =byGOVDetalhado!B5 -> 11744.709
A6: POPULAÇÃO | B6: =byGOVDetalhado!B6 -> 212583750
A7: TOTAL | B7: =SUM(B9:B16) -> 4222.222 | C7: =SUM(C9:C16) -> 35.949992 | D7: =SUM(D9:D16) -> 100 | E7: =(B7*1000000000)/$B$6 -> 19861.452
A9: BENS E SERVIÇOS | B9: =byGOVDetalhado!B11+byGOVDetalhado!B30+byGOVDetalhado!B40+byGOVDetalhado!B17+byGOVDetalhado!B20+byGOVDetalhado!B24+byGOVDetalhado!B36+byGOVDetalhado!B46 -> 1669.5638 | C9: =(B9/$B$5)*100 -> 14.215455 | D9: =(B9/$B$7)*100 -> 39.542303 | E9: =(B9*1000000000)/$B$6 -> 7853.6756
A10: SALÁRIOS E MÃO-DE-OBRA | B10: =byGOVDetalhado!B16+byGOVDetalhado!B26+byGOVDetalhado!B25+byGOVDetalhado!B23+byGOVDetalhado!B21+byGOVDetalhado!B35+byGOVDetalhado!B45+SUM(Contribuições!D14) -> 978.1427 | C10: =(B10/$B$5)*100 -> 8.328369 | D10: =(B10/$B$7)*100 -> 23.166539 | E10: =(B10*1000000000)/$B$6 -> 4601.211
A11: RENDA, LUCROS E GANHOS | B11: =byGOVDetalhado!B10+byGOVDetalhado!B33+byGOVDetalhado!B43+byGOVDetalhado!B19+SUM(Contribuições!D15:D21) -> 1059.4861 | C11: =(B11/$B$5)*100 -> 9.0209651 | D11: =(B11/$B$7)*100 -> 25.093093 | E11: =(B11*1000000000)/$B$6 -> 4983.8527
A12: PATRIMONIAIS | B12: =byGOVDetalhado!B14+byGOVDetalhado!B31+byGOVDetalhado!B32+byGOVDetalhado!B41+byGOVDetalhado!B42 -> 212.09076 | C12: =(B12/$B$5)*100 -> 1.8058409 | D12: =(B12/$B$7)*100 -> 5.0232024 | E12: =(B12*1000000000)/$B$6 -> 997.68095
A13: COMÉRCIO EXTERIOR | B13: =byGOVDetalhado!B13 -> 77.507333 | C13: =(B13/$B$5)*100 -> 0.65993405 | D13: =(B13/$B$7)*100 -> 1.8357001 | E13: =(B13*1000000000)/$B$6 -> 364.5967
A14: TAXAS | B14: =byGOVDetalhado!B15+byGOVDetalhado!B34+byGOVDetalhado!B44 -> 78.337977 | C14: =(B14/$B$5)*100 -> 0.66700654 | D14: =(B14/$B$7)*100 -> 1.8553733 | E14: =(B14*1000000000)/$B$6 -> 368.50407
A15: TRANSAÇÕES FINANCEIRAS | B15: =byGOVDetalhado!B12+byGOVDetalhado!B18 -> 67.379786 | C15: =(B15/$B$5)*100 -> 0.57370333 | D15: =(B15/$B$7)*100 -> 1.5958371 | E15: =(B15*1000000000)/$B$6 -> 316.95643
A16: DEMAIS | B16: =byGOVDetalhado!B22-SUM(Contribuições!D14:D21)+byGOVDetalhado!B27+byGOVDetalhado!B37+byGOVDetalhado!B47 -> 79.713516 | C16: =(B16/$B$5)*100 -> 0.67871853 | D16: =(B16/$B$7)*100 -> 1.8879518 | E16: =(B16*1000000000)/$B$6 -> 374.97465
A17: Fonte: Elaboração Própria (Balanço Oficial da União, STN; Balanço dos Estados, STN; Finbra, STN; SRF)
A18: Tributos computados por categoria:
A19: - Bens e serviços: IPI e ICMS (Valor Adicionado); COFINS, PIS-PASEP, Contrib.Econômicas (inclusive CIDE), ISS (Cumulativos),
A20: Contribuição para PIN, Selo Especial de Controle, Lojas Francas e Royalties
A21: - Salários: Contrib. Previdência Social (INSS), Sistema S e Salário-Educação; FGTS; Contribuição Servidores (3 esferas), Contr.Rel a Desped. de Empreg. S/ Justa Causa,
A22: Contr. sobre Remuneracao Devida ao Trabalh.
A23: - Renda = IR, CSLL, IR Retido na Fonte por Estados e Municípios, Contribuições de Loteria Federal, Contribuições de Bingo e Contribuições de Melhoria
A24: - Patrimoniais = ITR; IPVA e ITCD; IPTU e ITBI.
A25: - Comércio Exterior = impostos sobre exportação e importação.
A26: - Taxas = 3 esferas de governo (inclui contribuição municipal de iluminação pública)
A27: - Transações Financeiras = IOF e CPMF.
A28: - Demais Tributos = outros tributos, incluindo receita da dívida ativa, multas e juros
C29: =B12+B13+B15+B16 -> 436.69139 | D29: =D9+D13+D15+D14 -> 44.829214
D30: =D11+D12 -> 30.116296

Sheet RD ESFERA
A1: Receita Tributária Disponível por Esfera de Governo: 2024
A3: Receita Disponível | B3: =byGOVDetalhado!B3 -> 2024
B4: R$ Bilhões | C4: % PIB | D4: % Total | E4: Per capita (R$)
A5: PIB | B5: =byGOVDetalhado!B5 -> 11744.709
A6: POPULAÇÃO | B6: =byGOVDetalhado!B6 -> 212583750
A7: RECEITA DISPONÍVEL | B7: =SUM(B9,B11,B13) -> 4222.222 | C7: =SUM(C9,C11,C13) -> 35.949992 | D7: =SUM(D9,D11,D13) -> 100 | E7: =(B7*1000000000)/$B$6 -> 19861.452
A9: UNIÃO | B9: =+'AD ESFERA'!B9-'RD ESFERA'!B17-'RD ESFERA'!B30 -> 2176.573 | C9: =+B9/B$5*100 -> 18.53237 | D9: =+C9/C$7*100 -> 51.550415 | E9: =(B9*1000000000)/$B$6 -> 10238.661
A11: ESTADOS | B11: =+'AD ESFERA'!B16-'RD ESFERA'!B41+'RD ESFERA'!B17 -> 1063.1729 | C11: =+B11/B$5*100 -> 9.052356 | D11: =+C11/C$7*100 -> 25.180411 | E11: =(B11*1000000000)/$B$6 -> 5001.1954
A13: MUNICÍPIOS | B13: =+'AD ESFERA'!B21+'RD ESFERA'!B30+'RD ESFERA'!B41 -> 982.47617 | C13: =+B13/B$5*100 -> 8.3652662 | D13: =+C13/C$7*100 -> 23.269174 | E13: =(B13*1000000000)/$B$6 -> 4621.5958
A15: Transferências Constitucionais
A17: União para Estados | B17: =SUM(B18:B28) -> 252.50396 | C17: =SUM(C18:C28) -> 2.149938 | D17: =SUM(D18:D28) -> 5.9803572 | E17: =(B17*1000000000)/$B$6 -> 1187.7858
A18: FPE | B18: =Transferencias!C4 -> 149.83113 | C18: =+B18/B$5*100 -> 1.275733 | D18: =+C18/C$7*100 -> 3.5486322 | E18: =(B18*1000000000)/$B$6 -> 704.80988
A19: FPEx | B19: =Transferencias!C5 -> 6.7654936 | C19: =+B19/B$5*100 -> 0.057604608 | D19: =+C19/C$7*100 -> 0.16023538 | E19: =(B19*1000000000)/$B$6 -> 31.825074
A20: IOF OURO | B20: =Transferencias!C6 -> 0.003691963 | C20: =+B20/B$5*100 -> 3.1435117e-05 | D20: =+C20/C$7*100 -> 8.7441234e-05 | E20: =(B20*1000000000)/$B$6 -> 0.017367099
A21: SEGURO REC. ICMS | B21: =Transferencias!C7 -> 3 | C21: =+B21/B$5*100 -> 0.025543417 | D21: =+C21/C$7*100 -> 0.071052635 | E21: =(B21*1000000000)/$B$6 -> 14.112085
A22: FUNDEB | B22: =Transferencias!C8 -> 36.667704 | C22: =+B22/B$5*100 -> 0.31220615 | D22: =+C22/C$7*100 -> 0.86844567 | E22: =(B22*1000000000)/$B$6 -> 172.48592
A23: SAL.EDUCAÇÃO | B23: =0.666666666666667*byGOVDetalhado!B25 -> 21.413814 | C23: =+B23/B$5*100 -> 0.18232733 | D23: =+C23/C$7*100 -> 0.50716931 | E23: =(B23*1000000000)/$B$6 -> 100.73119
A24: FEX 1/ | B24: =Transferencias!C10 -> 0 | C24: =+B24/B$5*100 -> 0 | D24: =+C24/C$7*100 -> 0 | E24: =(B24*1000000000)/$B$6 -> 0
A25: CIDE | B25: =Transferencias!C11 -> 0.73765313 | C25: =+B25/B$5*100 -> 0.0062807272 | D25: =+C25/C$7*100 -> 0.017470733 | E25: =(B25*1000000000)/$B$6 -> 3.4699413
A26: AFE | B26: =Transferencias!C12 -> 0 | C26: =+B26/B$5*100 -> 0 | D26: =+C26/C$7*100 -> 0 | E26: =(B26*1000000000)/$B$6 -> 0
A27: LC 201/2023 | B27: =Transferencias!C13 -> 0.67448 | C27: =+B27/B$5*100 -> 0.0057428413 | D27: =+C27/C$7*100 -> 0.015974527 | E27: =(B27*1000000000)/$B$6 -> 3.1727731
A28: ROYALTIES E PARTICIPAÇÕES | B28: =Transferencias!C14 -> 33.409992 | C28: =+B28/B$5*100 -> 0.28446845 | D28: =+C28/C$7*100 -> 0.79128933 | E28: =(B28*1000000000)/$B$6 -> 157.16155
A30: União para Municípios | B30: =SUM(B31:B39) -> 306.13701 | C30: =SUM(C31:C39) -> 2.6065951 | D30: =SUM(D31:D39) -> 7.2506137 | E30: =(B30*1000000000)/$B$6 -> 1440.0772 | H30: =(C30+C41)/C13 -> 0.63378584
A31: FPM | B31: =Transferencias!C17 -> 177.03414 | C31: =+B31/B$5*100 -> 1.5073523 | D31: =+C31/C$7*100 -> 4.192914 | E31: =(B31*1000000000)/$B$6 -> 832.77361
A32: ITR | B32: =Transferencias!C18 -> 2.5175991 | C32: =+B32/B$5*100 -> 0.021436028 | D32: =+C32/C$7*100 -> 0.05962735 | E32: =(B32*1000000000)/$B$6 -> 11.842858
A33: IOF OURO | B33: =Transferencias!C19 -> 0.008614569 | C33: =+B33/B$5*100 -> 7.334851e-05 | D33: =+C33/C$7*100 -> 0.00020402928 | E33: =(B33*1000000000)/$B$6 -> 0.040523177
A34: SEGURO REC. ICMS | B34: =Transferencias!C20 -> 0.98556338 | C34: =+B34/B$5*100 -> 0.0083915521 | D34: =+C34/C$7*100 -> 0.023342292 | E34: =(B34*1000000000)/$B$6 -> 4.6361181
A35: FUNDEB | B35: =Transferencias!C21 -> 89.855047 | C35: =+B35/B$5*100 -> 0.76506832 | D35: =+C35/C$7*100 -> 2.128146 | E35: =(B35*1000000000)/$B$6 -> 422.6807
A36: FEX 1/ | B36: =Transferencias!C22 -> 0 | C36: =+B36/B$5*100 -> 0 | D36: =+C36/C$7*100 -> 0 | E36: =(B36*1000000000)/$B$6 -> 0
A37: CIDE | B37: =Transferencias!C23 -> 0.24155149 | C37: =+B37/B$5*100 -> 0.0020566835 | D37: =+C37/C$7*100 -> 0.0057209567 | E37: =(B37*1000000000)/$B$6 -> 1.1362651
A38: AFM | B38: =Transferencias!C24 -> 0.3139165 | C38: =+B38/B$5*100 -> 0.0026728334 | D38: =+C38/C$7*100 -> 0.0074348649 | E38: =(B38*1000000000)/$B$6 -> 1.4766721
A39: ROYALTIES E PARTICIPAÇÕES | B39: =Transferencias!C25 -> 35.180577 | C39: =+B39/B$5*100 -> 0.29954405 | D39: =+C39/C$7*100 -> 0.83322423 | E39: =(B39*1000000000)/$B$6 -> 165.49043
A41: Estados para Municípios | B41: =SUM(B42:B46) -> 316.54247 | C41: =SUM(C42:C46) -> 2.6951921 | D41: =SUM(D42:D46) -> 7.497059 | E41: =(B41*1000000000)/$B$6 -> 1489.0248
A42: ICMS | B42: =0.25*(byGOVDetalhado!B30-Transferencias!C31-Transferencias!C35) -> 161.08286 | C42: =+B42/B$5*100 -> 1.3715355 | D42: =+C42/C$7*100 -> 3.8151206 | E42: =(B42*1000000000)/$B$6 -> 757.73835
A43: IPVA | B43: =0.5*byGOVDetalhado!B31 -> 43.766561 | C43: =+B43/B$5*100 -> 0.37264917 | D43: =+C43/C$7*100 -> 1.0365765 | E43: =(B43*1000000000)/$B$6 -> 205.87915
A44: FPEX | B44: =Transferencias!C30 -> 1.6913734 | C44: =+B44/B$5*100 -> 0.014401152 | D44: =+C44/C$7*100 -> 0.040058846 | E44: =(B44*1000000000)/$B$6 -> 7.9562685
A45: FUNDEB | B45: =Transferencias!C31 -> 109.83306 | C45: =+B45/B$5*100 -> 0.93517056 | D45: =+C45/C$7*100 -> 2.6013095 | E45: =(B45*1000000000)/$B$6 -> 516.65784
A46: LC 201/2023 | B46: =Transferencias!C32 -> 0.16862 | C46: =+B46/B$5*100 -> 0.0014357103 | D46: =+C46/C$7*100 -> 0.0039936318 | E46: =(B46*1000000000)/$B$6 -> 0.79319327
A47: Elaboração própria. Fontes primárias: STN, ANP e Aneel.
A48: 1/ Fundo destinado ao fomento das exportações (até 2004, era considerado como parcela da Lei Kandir)
...

Sheet RD ESFERA DETALHADA
A1: Receita Tributária Disponível por Esfera de Governo: 2024
A3: Receita Disponível | B3: =byGOVDetalhado!B3 -> 2024
B4: R$ Bilhões | C4: % PIB | D4: % Total | E4: Per capita (R$)
A5: PIB | B5: =byGOVDetalhado!B5 -> 11744.709
A6: POPULAÇÃO | B6: =byGOVDetalhado!B6 -> 212583750
A7: RECEITA DISPONÍVEL | B7: =SUM(B9,B14,B16) -> 4222.222 | C7: =SUM(C9,C14,C16) -> 35.949992 | D7: =SUM(D9,D14,D16) -> 100 | E7: =(B7*1000000000)/$B$6 -> 19861.452
A9: UNIÃO | B9: ='AD ESFERA'!B9-'RD ESFERA DETALHADA'!B20-'RD ESFERA DETALHADA'!B33 -> 2176.573 | C9: =+B9/B$5*100 -> 18.53237 | D9: =+C9/C$7*100 -> 51.550415 | E9: =(B9*1000000000)/$B$6 -> 10238.661
A10: Contas Privadas | B10: =byGOVDetalhado!B23+byGOVDetalhado!B26+(0.4*byGOVDetalhado!B20) -> 261.25211 | C10: =+B10/B$5*100 -> 2.2244239 | D10: =+C10/C$7*100 -> 6.1875504 | E10: =(B10*1000000000)/$B$6 -> 1228.9374
A11: Seguridade Social | B11: =byGOVDetalhado!B16+byGOVDetalhado!B17+byGOVDetalhado!B18+byGOVDetalhado!B19+(0.6*byGOVDetalhado!B20)+byGOVDetalhado!B21+byGOVDetalhado!B22 -> 1221.1286 | C11: =+B11/B$5*100 -> 10.397266 | D11: =+C11/C$7*100 -> 28.921468 | E11: =(B11*1000000000)/$B$6 -> 5744.2235
A12: Fiscal | B12: =B9-B10-B11 -> 694.19226 | C12: =+B12/B$5*100 -> 5.9106808 | D12: =+C12/C$7*100 -> 16.441397 | E12: =(B12*1000000000)/$B$6 -> 3265.5001
A14: ESTADOS | B14: ='AD ESFERA'!B16-'RD ESFERA DETALHADA'!B44+'RD ESFERA DETALHADA'!B20 -> 1063.3415 | C14: =+B14/B$5*100 -> 9.0537917 | D14: =+C14/C$7*100 -> 25.184405 | E14: =(B14*1000000000)/$B$6 -> 5001.9886
A16: MUNICÍPIOS | B16: ='AD ESFERA'!B21+'RD ESFERA DETALHADA'!B33+'RD ESFERA DETALHADA'!B44 -> 982.30755 | C16: =+B16/B$5*100 -> 8.3638304 | D16: =+C16/C$7*100 -> 23.26518 | E16: =(B16*1000000000)/$B$6 -> 4620.8026
A18: Transferências Constitucionais
A20: União para Estados | B20: =SUM(B21:B31) -> 252.50396 | C20: =SUM(C21:C31) -> 2.149938 | D20: =SUM(D21:D31) -> 5.9803572 | E20: =(B20*1000000000)/$B$6 -> 1187.7858
A21: FPE | B21: ='RD ESFERA'!B18 -> 149.83113 | C21: =+B21/B$5*100 -> 1.275733 | D21: =+C21/C$7*100 -> 3.5486322 | E21: =(B21*1000000000)/$B$6 -> 704.80988
A22: FPEx | B22: ='RD ESFERA'!B19 -> 6.7654936 | C22: =+B22/B$5*100 -> 0.057604608 | D22: =+C22/C$7*100 -> 0.16023538 | E22: =(B22*1000000000)/$B$6 -> 31.825074
A23: IOF OURO | B23: ='RD ESFERA'!B20 -> 0.003691963 | C23: =+B23/B$5*100 -> 3.1435117e-05 | D23: =+C23/C$7*100 -> 8.7441234e-05 | E23: =(B23*1000000000)/$B$6 -> 0.017367099
A24: SEGURO REC. ICMS | B24: ='RD ESFERA'!B21 -> 3 | C24: =+B24/B$5*100 -> 0.025543417 | D24: =+C24/C$7*100 -> 0.071052635 | E24: =(B24*1000000000)/$B$6 -> 14.112085
A25: FUNDEB | B25: ='RD ESFERA'!B22 -> 36.667704 | C25: =+B25/B$5*100 -> 0.31220615 | D25: =+C25/C$7*100 -> 0.86844567 | E25: =(B25*1000000000)/$B$6 -> 172.48592
A26: SAL.EDUCAÇÃO | B26: ='RD ESFERA'!B23 -> 21.413814 | C26: =+B26/B$5*100 -> 0.18232733 | D26: =+C26/C$7*100 -> 0.50716931 | E26: =(B26*1000000000)/$B$6 -> 100.73119
A27: FEX 1/ | B27: ='RD ESFERA'!B24 -> 0 | C27: =+B27/B$5*100 -> 0 | D27: =+C27/C$7*100 -> 0 | E27: =(B27*1000000000)/$B$6 -> 0
A28: CIDE | B28: ='RD ESFERA'!B25 -> 0.73765313 | C28: =+B28/B$5*100 -> 0.0062807272 | D28: =+C28/C$7*100 -> 0.017470733 | E28: =(B28*1000000000)/$B$6 -> 3.4699413
A29: AFE | B29: ='RD ESFERA'!B26 -> 0 | C29: =+B29/B$5*100 -> 0 | D29: =+C29/C$7*100 -> 0 | E29: =(B29*1000000000)/$B$6 -> 0
A30: LC 201/2023 | B30: ='RD ESFERA'!B27 -> 0.67448 | C30: =+B30/B$5*100 -> 0.0057428413 | D30: =+C30/C$7*100 -> 0.015974527 | E30: =(B30*1000000000)/$B$6 -> 3.1727731
A31: ROYALTIES E PARTICIPAÇÕES | B31: ='RD ESFERA'!B28 -> 33.409992 | C31: =+B31/B$5*100 -> 0.28446845 | D31: =+C31/C$7*100 -> 0.79128933 | E31: =(B31*1000000000)/$B$6 -> 157.16155
A33: União para Municípios | B33: =SUM(B34:B42) -> 306.13701 | C33: =SUM(C34:C42) -> 2.6065951 | D33: =SUM(D34:D42) -> 7.2506137 | E33: =(B33*1000000000)/$B$6 -> 1440.0772
A34: FPM | B34: ='RD ESFERA'!B31 -> 177.03414 | C34: =+B34/B$5*100 -> 1.5073523 | D34: =+C34/C$7*100 -> 4.192914 | E34: =(B34*1000000000)/$B$6 -> 832.77361
A35: ITR | B35: ='RD ESFERA'!B32 -> 2.5175991 | C35: =+B35/B$5*100 -> 0.021436028 | D35: =+C35/C$7*100 -> 0.05962735 | E35: =(B35*1000000000)/$B$6 -> 11.842858
A36: IOF OURO | B36: ='RD ESFERA'!B33 -> 0.008614569 | C36: =+B36/B$5*100 -> 7.334851e-05 | D36: =+C36/C$7*100 -> 0.00020402928 | E36: =(B36*1000000000)/$B$6 -> 0.040523177
A37: SEGURO REC. ICMS | B37: ='RD ESFERA'!B34 -> 0.98556338 | C37: =+B37/B$5*100 -> 0.0083915521 | D37: =+C37/C$7*100 -> 0.023342292 | E37: =(B37*1000000000)/$B$6 -> 4.6361181
A38: FUNDEB | B38: ='RD ESFERA'!B35 -> 89.855047 | C38: =+B38/B$5*100 -> 0.76506832 | D38: =+C38/C$7*100 -> 2.128146 | E38: =(B38*1000000000)/$B$6 -> 422.6807
A39: FEX 1/ | B39: ='RD ESFERA'!B36 -> 0 | C39: =+B39/B$5*100 -> 0 | D39: =+C39/C$7*100 -> 0 | E39: =(B39*1000000000)/$B$6 -> 0
A40: CIDE | B40: ='RD ESFERA'!B37 -> 0.24155149 | C40: =+B40/B$5*100 -> 0.0020566835 | D40: =+C40/C$7*100 -> 0.0057209567 | E40: =(B40*1000000000)/$B$6 -> 1.1362651
A41: AFM | B41: ='RD ESFERA'!B38 -> 0.3139165 | C41: =+B41/B$5*100 -> 0.0026728334 | D41: =+C41/C$7*100 -> 0.0074348649 | E41: =(B41*1000000000)/$B$6 -> 1.4766721
A42: ROYALTIES E PARTICIPAÇÕES | B42: ='RD ESFERA'!B39 -> 35.180577 | C42: =+B42/B$5*100 -> 0.29954405 | D42: =+C42/C$7*100 -> 0.83322423 | E42: =(B42*1000000000)/$B$6 -> 165.49043
A44: Estados para Municípios | B44: =SUM(B45:B48) -> 316.37385 | C44: =SUM(C45:C48) -> 2.6937564 | D44: =SUM(D45:D48) -> 7.3558896 | E44: =(B44*1000000000)/$B$6 -> 1488.2316
A45: ICMS | B45: ='RD ESFERA'!B42 -> 161.08286 | C45: =+B45/B$5*100 -> 1.3715355 | D45: =SUM(D46:D48) -> 3.6779448 | E45: =(B45*1000000000)/$B$6 -> 757.73835
A46: IPVA | B46: ='RD ESFERA'!B43 -> 43.766561 | C46: =+B46/B$5*100 -> 0.37264917 | D46: =+C46/C$7*100 -> 1.0365765 | E46: =(B46*1000000000)/$B$6 -> 205.87915
A47: FPEX | B47: ='RD ESFERA'!B44 -> 1.6913734 | C47: =+B47/B$5*100 -> 0.014401152 | D47: =+C47/C$7*100 -> 0.040058846 | E47: =(B47*1000000000)/$B$6 -> 7.9562685
A48: FUNDEB | B48: ='RD ESFERA'!B45 -> 109.83306 | C48: =+B48/B$5*100 -> 0.93517056 | D48: =+C48/C$7*100 -> 2.6013095 | E48: =(B48*1000000000)/$B$6 -> 516.65784
...

Sheet Impostos
A2: 11110101 | B2: IMPOSTO SOBRE A IMPORTACAO-PRINCIPAL | C2: 7.7503109e+10 | D2: =C2/1000000000 -> 77.503109
A3: 11110102 | B3: IMPOSTO SOBRE A IMPORTACAO-MULTAS JUROS | C3: 2.3361024e+08 | D3: =C3/1000000000 -> 0.23361024
A4: 11110103 | B4: IMPOSTO SOBRE A IMPORTACAO-DIVIDA ATIVA | C4: -8834799.4 | D4: =C4/1000000000 -> -0.0088347994
A5: 11110107 | B5: IMPOSTO SOBRE A IMPORTACAO-MULTAS DIV.ATIVA | C5: 6292210.1 | D5: =C5/1000000000 -> 0.0062922101
A6: 11110108 | B6: IMPOSTO SOBRE A IMPORTACAO-JUROS DIVIDA ATIVA | C6: 15143752 | D6: =C6/1000000000 -> 0.015143752
A7: 11110201 | B7: IMPOSTO SOBRE A EXPORTACAO-PRINCIPAL | C7: 4224369.3 | D7: =C7/1000000000 -> 0.0042243693
A8: 11110202 | B8: IMPOSTO SOBRE A EXPORTACAO-MUL.JUR. | C8: -168368.08 | D8: =C8/1000000000 -> -0.00016836808
A9: 11110203 | B9: IMPOSTO SOBRE A EXPORTACAO-DIVIDA ATIVA | C9: 1612783.1 | D9: =C9/1000000000 -> 0.0016127831
A10: 11110207 | B10: IMPOSTO SOBRE A EXPORTACAO-MULTAS DIV.ATIVA | C10: 383560.43 | D10: =C10/1000000000 -> 0.00038356043
A11: 11110208 | B11: IMPOSTO SOBRE A EXPORTACAO-JUROS DIVIDA ATIVA | C11: 7049841.8 | D11: =C11/1000000000 -> 0.0070498418
A12: 11120111 | B12: ITR-MUNICIPIOS CONVENIADOS-PRINCIPAL | C12: 2.5923832e+09 | D12: =C12/1000000000 -> 2.5923832
A13: 11120112 | B13: ITR-MUNICIPIOS CONVENIADOS-MULTAS E JUROS | C13: 1.6800421e+08 | D13: =C13/1000000000 -> 0.16800421
... A57: 11199904 | B57: OUTROS IMPOSTOS-DIVIDA ATIVA-MULTAS E JUROS | C57: 110504.56 | D57: =C57/1000000000 -> 0.00011050456
C58: 0 | D58: =C58/1000000000 -> 0
B59: TAXA | C59: =SUM(C60:C90) -> 9.4437154e+09 | D59: =C59/1000000000 -> 9.4437154
A60: 11210101 | B60: TAXAS INSPECAO,CONTROLE E FISCALIZACAO-PRINC. | C60: 5.810899e+09 | D60: =C60/1000000000 -> 5.810899
A61: 11210102 | B61: TAXAS INSPECAO,CONTROLE E FISCALIZ.-MUL.JUR. | C61: 2065280 | D61: =C61/1000000000 -> 0.00206528
A62: 11210103 | B62: TAXAS INSPECAO,CONTROLE E FISCALIZACAO-DIV.AT | C62: 48720230 | D62: =C62/1000000000 -> 0.04872023
A63: 11210104 | B63: TX.INSP,CONTROL.E FISCALIZ.-DIV.AT.-MUL.JUR. | C63: 124859.7 | D63: =C63/1000000000 -> 0.0001248597
A64: 11210211 | B64: TX.FISC.INST-TFI-NAO.POSI.ORBITAIS/PRC | C64: 94195953 | D64: =C64/1000000000 -> 0.094195953
A65: 11210213 | B65: TX.FISC.INST-TFI-NAO.POSI.ORBITAIS/DA.PRC | C65: 460413.18 | D65: =C65/1000000000 -> 0.00046041318
A66: 11210214 | B66: TX.FISC.INST-TFI-NAO.POSI.ORBITAIS/DA.MLT+JRS | C66: 12336.29 | D66: =C66/1000000000 -> 1.233629e-05
A67: 11210221 | B67: TX.FISC.FUNC-TFF-NAO.POSI.ORBITAIS/PRC | C67: 7.6346077e+08 | D67: =C67/1000000000 -> 0.76346077
A68: 11210223 | B68: TX.FISC.FUNC-TFF-NAO.POSI.ORBITAIS/DA.PRC | C68: 2144470 | D68: =C68/1000000000 -> 0.00214447
A69: 11210224 | B69: TX.FISC.FUNC-TFF-NAO.POSI.ORBITAIS/DA.MLT+JRS | C69: 45809.45 | D69: =C69/1000000000 -> 4.580945e-05
A70: 11210231 | B70: TX.FISC.INST-TFI-POSICOES.ORBITAIS/PRC | C70: 7402469.4 | D70: =C70/1000000000 -> 0.0074024694
A71: 11210233 | B71: TX.FISC.INST-TFI-POSICOES.ORBITAIS/DA.PRC | C71: 0 | D71: =C71/1000000000 -> 0
A72: 11210241 | B72: TX.FISC.FUNC-TFF-POSICOES.ORBITAIS/PRC | C72: 6579184.2 | D72: =C72/1000000000 -> 0.0065791842
A73: 11210301 | B73: TX.CONTROLE E FISCALIZ.PROD.QUIMICOS-PRINC. | D73: =C73/1000000000 -> 0
A74: 11210401 | B74: TAXA DE CONTROLE E FISC.AMBIENTAL-PRINCIPAL | C74: 5.2841445e+08 | D74: =C74/1000000000 -> 0.52841445
A75: 11210402 | B75: TAXA DE CONTROLE E FISC.AMBIENTAL-MUL.JUR. | C75: 107.84 | D75: =C75/1000000000 -> 1.0784e-07
A76: 11210403 | B76: TAXA DE CONTROLE E FISC.AMBIENTAL-DIV.ATIVA | C76: 27345028 | D76: =C76/1000000000 -> 0.027345028
A77: 11210501 | B77: TX.CONTR.E FISC.PESCA E AQUICULTURA-PRINC. | C77: 18313070 | D77: =C77/1000000000 -> 0.01831307
A78: 11210502 | B78: TX.CONTR.E FISC.PESCA E AQUICULTURA-MUL.JUR. | C78: 26 | D78: =C78/1000000000 -> 2.6e-08
A79: 11210601 | B79: TAXA DE UTILIZACAO DO SISCOMEX-PRINCIPAL | C79: 6.3208533e+08 | D79: =C79/1000000000 -> 0.63208533
A80: 11210701 | B80: TAXA DE UTILIZACAO DO MERCANTE-TUM-PRINC. | C80: 24570059 | D80: =C80/1000000000 -> 0.024570059
A81: 11210702 | B81: TAXA DE UTILIZACAO DO MERCANTE-TUM-MUL.JUR. | D81: =C81/1000000000 -> 0
A82: 11210801 | B82: TX.FISC.EXPL.COM.LOT.AP.QUOTA FIXA-PRINCIPAL | C82: 68427 | D82: =C82/1000000000 -> 6.8427e-05
A83: 11210901 | B83: TX.AUTORIZ.DISTRIB.GRATUITA PREMIOS-PRINCIPAL | C83: 21443412 | D83: =C83/1000000000 -> 0.021443412
A84: 11210902 | B84: TX.AUTORIZ.DISTRIB.GRATUITA PREMIOS-MUL.JUR. | C84: 0.04 | D84: =C84/1000000000 -> 4e-11
...

Sheet Contribuições
A1: CÓDIGO | B1: RECEITAS DE CONTRIBUIÇÕES | C1: TOTAL | F1: Referência
A2: 12210701 | B2: CIDE-REMESSAS AO EXTERIOR-PRINCIPAL | C2: 1.5596727e+10 | D2: =C2/1000000000 -> 15.596727 | E2: CIDE | F2: Contribuições Econômicas (4)
A3: 12210811 | B3: CIDE-COMBUSTIVEIS-IMPORTACAO-PRINCIPAL | C3: 3.6169301e+08 | D3: =C3/1000000000 -> 0.36169301 | E3: CIDE | F3: Contribuições Econômicas (4)
A4: 12210821 | B4: CIDE-COMBUSTIVEIS-COMERCIALIZACAO-PRINCIPAL | C4: 3.0296646e+09 | D4: =C4/1000000000 -> 3.0296646 | E4: CIDE | F4: Contribuições Econômicas (4)
A5: 12211211 | B5: CONTR.ATIV.IND.RURAIS-CIDE IND.RURAL-PRINC. | C5: 2.7441e+09 | D5: =C5/1000000000 -> 2.7441 | E5: CIDE RURAL | F5: Contribuições Econômicas (4)
A6: 12211301 | B6: ADIC.CONTR.PREV.FOLHA-CIDE REF.AGR.-PRINC. | C6: 21398045 | D6: =C6/1000000000 -> 0.021398045 | E6: CIDE RURAL | F6: Contribuições Econômicas (4)
A7: 12110101 | B7: COFINS S/FATURAMENTO-NAO OPT.SIMP.NAC-PRINC. | C7: 3.2896385e+11 | D7: =C7/1000000000 -> 328.96385 | E7: COFINS
A8: 12110201 | B8: COFINS S/FATURAMENTO-OPT.SIMP.NAC-PRINC. | C8: 2.4631102e+10 | D8: =C8/1000000000 -> 24.631102 | E8: COFINS
A9: 12114901 | B9: COFINS SOBRE O FATURAMENTO-PARCELAM.-PRINC. | C9: 1.9757552e+08 | D9: =C9/1000000000 -> 0.19757552 | E9: COFINS
A10: 12191011 | B10: CONTR.MOV.TRANSM.VAL.CRED.DIR.NAT.FIN.-PRINC. | C10: -22443285 | D10: =C10/1000000000 -> -0.022443285 | E10: CPMF
A11: 12130101 | B11: CSLL-CONTRIBUINTES NAO OPT.SIMP.NAC-PRINC. | C11: 1.4991125e+11 | D11: =C11/1000000000 -> 149.91125 | E11: CSLL
A12: 12130201 | B12: CSLL-CONTRIBUINTES OPT.SIMPLES NAC.-PRINC | C12: 1.0015628e+10 | D12: =C12/1000000000 -> 10.015628 | E12: CSLL
A13: 12134901 | B13: CSLL-PARCELAMENTOS-PRINCIPAL | C13: 6.7982194e+08 | D13: =C13/1000000000 -> 0.67982194 | E13: CSLL
A14: 12190321 | B14: CONTR.S/REMUN.DEVIDA AO TRABALHADOR-PRINCIPAL | C14: 94069197 | D14: =C14/1000000000 -> 0.094069197 | E14: FGTS ADICIONAL | F14: Outras contribuições sociais (3)
A15: 12170111 | B15: CONTRIBUICAO SOBRE A LOTERIA FEDERAL-PRINCIP. | C15: 41612230 | D15: =C15/1000000000 -> 0.04161223 | E15: JOGOS | F15: Outras contribuições sociais (3)
A16: 12170211 | B16: CONTRIBUICAO SOBRE LOTERIAS ESPORTIVAS-PRINC. | C16: 5796539.3 | D16: =C16/1000000000 -> 0.0057965393 | E16: JOGOS | F16: Outras contribuições sociais (3)
A17: 12170411 | B17: CONTRIB.S/LOTERIAS PROGNOST.NUMERICOS-PRINC. | C17: 4.3413857e+09 | D17: =C17/1000000000 -> 4.3413857 | E17: JOGOS | F17: Outras contribuições sociais (3)
A18: 12170611 | B18: CONTRIB.S/LOTERIA PROGNOST.ESPECIFICO-PRINC. | C18: 10502530 | D18: =C18/1000000000 -> 0.01050253 | E18: JOGOS | F18: Outras contribuições sociais (3)
A19: 12170711 | B19: CONTR.SOBRE LOT.APOSTAS DE QUOTA FIXA-PRINC. | C19: 24503.37 | D19: =C19/1000000000 -> 2.450337e-05 | E19: JOGOS | F19: Outras contribuições sociais (3)
A20: 12190111 | B20: CONTRIB.S/SORT.REALIZ.POR ENT.FILANT.-PRINC. | C20: 717575.23 | D20: =C20/1000000000 -> 0.00071757523 | E20: JOGOS | F20: Outras contribuições sociais (3)
A21: 12210301 | B21: CONTR.S/APOSTAS EM COMPETICOES HIPICAS-PRINC. | C21: 215169.77 | D21: =C21/1000000000 -> 0.00021516977 | E21: JOGOS | F21: Outras contribuições sociais (3)
A22: 12110103 | B22: COFINS S/FATURAMENTO-NAO OPT.SIMP.NAC-DIV.AT. | C22: 1.4108171e+08 | D22: =C22/1000000000 -> 0.14108171 | E22: MULTAS E DA
A23: 12110105 | B23: COFINS S/FATURAMENTO-NAO OPT.SIMP.NAC-MULTAS | C23: 8.824105e+08 | D23: =C23/1000000000 -> 0.8824105 | E23: MULTAS E DA
A24: 12110106 | B24: COFINS S/FATURAMENTO-NAO OPT.SIMP.NAC-JUROS | C24: 1.4262415e+09 | D24: =C24/1000000000 -> 1.4262415 | E24: MULTAS E DA
A25: 12110107 | B25: COFINS S/FATURAM.-NAO OPT.SIMP.NAC-MUL.DIV.AT | C25: 77323253 | D25: =C25/1000000000 -> 0.077323253 | E25: MULTAS E DA
A26: 12110108 | B26: COFINS S/FATURAM.-NAO OPT.SIMP.NAC-JUR.DIV.AT | C26: 2.3459711e+08 | D26: =C26/1000000000 -> 0.23459711 | E26: MULTAS E DA
A27: 12110203 | B27: COFINS S/FATURAMENTO-OPT.SIMP.NAC-DIV.AT. | C27: 5.2423345e+08 | D27: =C27/1000000000 -> 0.52423345 | E27: MULTAS E DA
A28: 12110205 | B28: COFINS S/FATURAMENTO-OPT.SIMP.NAC-MULTAS | C28: 3.8903605e+08 | D28: =C28/1000000000 -> 0.38903605 | E28: MULTAS E DA
A29: 12110206 | B29: COFINS S/FATURAMENTO-OPT.SIMP.NAC-JUROS | C29: 2.7934344e+08 | D29: =C29/1000000000 -> 0.27934344 | E29: MULTAS E DA
A30: 12110207 | B30: COFINS S/FATURAMENTO-OPT.SIMP.NAC-MUL.DIV.AT | C30: 72266031 | D30: =C30/1000000000 -> 0.072266031 | E30: MULTAS E DA
A31: 12110208 | B31: COFINS S/FATURAMENTO-OPT.SIMP.NAC-JUR.DIV.AT | C31: 83446164 | D31: =C31/1000000000 -> 0.083446164 | E31: MULTAS E DA
A32: 12114903 | B32: COFINS SOBRE O FATURAMENTO-PARCELAM.-DIV.AT. | C32: 4.6226362e+09 | D32: =C32/1000000000 -> 4.6226362 | E32: MULTAS E DA
A33: 12114905 | B33: COFINS SOBRE O FATURAMENTO-PARCELAM.-MULTAS | C33: -21806039 | D33: =C33/1000000000 -> -0.021806039 | E33: MULTAS E DA
... A138: 12219924 | B138: OUTR.CONTR.ECON-ARREC.PROJ.RFB-DIV.AT.MUL/JUR | C138: 6126078.6 | D138: =C138/1000000000 -> 0.0061260786 | E138: MULTAS E DA
A139: 12210401 | B139: CONDECINE-PRINCIPAL | C139: 1.2080445e+09 | D139: =C139/1000000000 -> 1.2080445 | E139: OUTRAS CONTR. ECO. | F139: Contribuições Econômicas (4)
A140: 12210501 | B140: COTA-PARTE DO AFRMM-PRINCIPAL | C140: 4.3918702e+09 | D140: =C140/1000000000 -> 4.3918702 | E140: OUTRAS CONTR. ECO. | F140: Contribuições Econômicas (4)
A141: 12160111 | B141: CONTR.P/FUNDOS ASSIST.MED-POLIC.MILIT-PRINC. | C141: 20297228 | D141: =C141/1000000000 -> 0.020297228 | E141: OUTRAS. CONTR. SOC. | F141: Outras contribuições sociais (3)
A142: 12160211 | B142: CONTR.P/FUNDOS ASSIST.MED-BOMB.MILIT.-PRINC. | C142: 24146378 | D142: =C142/1000000000 -> 0.024146378 | E142: OUTRAS. CONTR. SOC. | F142: Outras contribuições sociais (3)
A143: 12160511 | B143: CONTR.FUNDOS ASS.MED.HOSP-F.ARM.-PRINC. | C143: 2.0853316e+09 | D143: =C143/1000000000 -> 2.0853316 | E143: OUTRAS. CONTR. SOC. | F143: Outras contribuições sociais (3)
A144: 12199911 | B144: DEM.CONTR.SOC.NAO ARREC.NAO PROJ.RFB-PRINC. | C144: 783.86 | D144: =C144/1000000000 -> 7.8386e-07 | E144: OUTRAS. CONTR. SOC. | F144: Outras contribuições sociais (3)
...

Sheet Patrimoniais
A2: 13410211 | B2: ROYALT.PROD.PETRO.EM TERRA-CONCESSAO-PRINC. | C2: 8.3026625e+08 | D2: =C2/1000000000 -> 0.83026625 | E2: ROYALTIES PETROL.
A3: 13410221 | B3: ROY.PETRO.PLAT-COM.ANTES 3/12/12-P.SAL-PRINC. | C3: 7.9379874e+09 | D3: =C3/1000000000 -> 7.9379874 | E3: ROYALTIES PETROL.
A4: 13410231 | B4: ROY.PETRO.PLAT-COM.ANTES 3/12/12-DEMAIS-PRINC | C4: 4.0673608e+09 | D4: =C4/1000000000 -> 4.0673608 | E4: ROYALTIES PETROL.
A5: 13410241 | B5: ROYAL.PETRO.PLAT.-COM.A PARTIR 3/12/12-PRINC. | C5: 4.929475e+09 | D5: =C5/1000000000 -> 4.929475 | E5: ROYALTIES PETROL.
A6: 13410311 | B6: ROYAL.EXCED.PROD.PETRO.TERRA(QQ SIT.)-PRINC. | C6: 6.7449146e+08 | D6: =C6/1000000000 -> 0.67449146 | E6: ROYALTIES PETROL.
A7: 13410321 | B7: ROY.EXC.PETRO.PLAT-CM.ANT.3/12/12-P.SAL-PRINC | C7: 7.9031818e+09 | D7: =C7/1000000000 -> 7.9031818 | E7: ROYALTIES PETROL.
A8: 13410331 | B8: ROY.EXC.PETRO.PLAT-COM.ANT.3/12/12-DEM.-PRINC | C8: 3.8124704e+09 | D8: =C8/1000000000 -> 3.8124704 | E8: ROYALTIES PETROL.
A9: 13410341 | B9: ROY.EXC.PETRO.PLAT-COM.A PARTIR 3/12/12-PRINC | C9: 4.9294758e+09 | D9: =C9/1000000000 -> 4.9294758 | E9: ROYALTIES PETROL.
A10: 13410421 | B10: P.ESP.PETRO.PLAT-COM.ANT.3/12/12-P.SAL-PRINC. | C10: 3.6300417e+10 | D10: =C10/1000000000 -> 36.300417 | E10: ROYALTIES PETROL.
A11: 13410431 | B11: P.ESP.PETRO.PLAT-COM.ANT.3/12/12-DEMAIS-PRINC | C11: 1.6963234e+09 | D11: =C11/1000000000 -> 1.6963234 | E11: ROYALTIES PETROL.
A12: 13410441 | B12: P.ESP.PETRO.PLAT-COM.A PARTIR 3/12/12-PRINC. | C12: 1.1779757e+09 | D12: =C12/1000000000 -> 1.1779757 | E12: ROYALTIES PETROL.
A13: 13410501 | B13: PART.PROPR.TERRA-CONTRATO CONCESSAO-PRINC. | C13: 24800.69 | D13: =C13/1000000000 -> 2.480069e-05 | E13: ROYALTIES PETROL.
... A22: 13450332 | B22: UTIL.REC.HID-DEM.EMPRESAS-PRORROG.OUT-MUL.JUR | C22: 12456.8 | D22: =C22/1000000000 -> 1.24568e-05 | E22: MULTAS E DA
D24: =D16+D19+D20+D22 -> 0.02307046

Sheet Multas
A2: 19990811 | B2: PREMIO DO SEGURO OBRIGATORIO DPVAT-PRINCIPAL | C2: 424790.04 | D2: =C2/1000000000 -> 0.00042479004

Sheet Estados
A1: ANO | B1: 2022
A2: ICMS | B2: 828.14597
A3: IPVA | B3: 87.533122
A4: ITCD | B4: 18.575221
A5: IRRF | B5: 81.090062
A6: TAXAS | B6: 48.769144
A7: CONTR. SOCIAIS | B7: 55.32654
A8: CONTR. ECONÔMICAS E DE MELHORIA | B8: 7.7713305
A9: MULTAS, JUROS E DÍVIDA ATIVA | B9: 0
A10: ISS | B10: 3.4879531
A11: IPTU | B11: 1.3351333
A12: ITBI | B12: 0.62133267

Sheet Municipios
A1: Rótulos de Linha | B1: IRRF | C1: IPTU | D1: ITBI | E1: ISS | F1: TAXAS | G1: CON. MELHORIA | H1: CON. SOCIAIS | I1: CON. ECONOMICAS | J1: COSIP
B2: 48.838753 | C2: 76.29925 | D2: 24.481179 | E2: 139.14584 | F2: 20.125118 | G2: 0.4306863 | H2: 29.224977 | I2: 0 | J2: 15.806464

Sheet Transferencias
A1: Transferências Constitucionais | B1: 2024
A3: União para Estados
A4: FPE | B4: 149831128016 | C4: =+B4/1000000000 -> 149.83113
A5: FPEx | B5: 6765493569 | C5: =+B5/1000000000 -> 6.7654936
A6: IOF OURO | B6: 3691963 | C6: =+B6/1000000000 -> 0.003691963
A7: SEGURO REC. ICMS | B7: 3000000000 | C7: =+B7/1000000000 -> 3
A8: FUNDEF/FUNDEB | B8: 3.6667704e+10 | C8: =+B8/1000000000 -> 36.667704
A9: SAL.EDUCAÇÃO | C9: =+B9/1000000000 -> 0
A10: FEX | B10: 0 | C10: =+B10/1000000000 -> 0
A11: CIDE | B11: 737653130 | C11: =+B11/1000000000 -> 0.73765313
A12: AFE | B12: 0 | C12: =+B12/1000000000 -> 0
A13: LC 201/2023 | B13: 674480000 | C13: =+B13/1000000000 -> 0.67448
A14: ROYALTIES E PARTICIPAÇÕES | B14: 33409992069 | C14: =+B14/1000000000 -> 33.409992
C15: =+B15/1000000000 -> 0
A16: União para Municípios | C16: =+B16/1000000000 -> 0
A17: FPM | B17: 177034137490 | C17: =+B17/1000000000 -> 177.03414
A18: ITR | B18: 2517599069 | C18: =+B18/1000000000 -> 2.5175991
A19: IOF OURO | B19: 8614569 | C19: =+B19/1000000000 -> 0.008614569
A20: SEGURO REC. ICMS | B20: 985563376 | C20: =+B20/1000000000 -> 0.98556338
A21: FUNDEF/FUNDEB | B21: 8.9855047e+10 | C21: =+B21/1000000000 -> 89.855047
A22: FEX | B22: 0 | C22: =+B22/1000000000 -> 0
A23: CIDE | B23: 241551492 | C23: =+B23/1000000000 -> 0.24155149
A24: AFM | B24: 313916500 | C24: =+B24/1000000000 -> 0.3139165
A25: ROYALTIES E PARTICIPAÇÕES | B25: 35180576528 | C25: =+B25/1000000000 -> 35.180577
C26: =+B26/1000000000 -> 0
A27: Estados para Municípios | C27: =+B27/1000000000 -> 0
A28: ICMS | C28: =+B28/1000000000 -> 0
A29: IPVA | C29: =+B29/1000000000 -> 0
A30: FPEx | B30: 1.6913734e+09 | C30: =+B30/1000000000 -> 1.6913734
A31: FUNDEF/FUNDEB | B31: 1.0983306e+11 | C31: =+B31/1000000000 -> 109.83306
A32: LC 201/2023 | B32: 168620000 | C32: =+B32/1000000000 -> 0.16862
C33: =+B33/1000000000 -> 0
A34: Estados para Estados | C34: =+B34/1000000000 -> 0
A35: FUNDEF/FUNDEB | B35: 7.3981471e+10 | C35: =+B35/1000000000 -> 73.981471

Sheet Gráficos
A3: União | B3: ='AD ESFERA'!D9/100 -> 0.64781386 | C3: ='RD ESFERA'!D9/100 -> 0.51550415 | F3: ='AD ESFERA'!C9 -> 23.288903 | G3: ='RD ESFERA'!C9 -> 18.53237
A4: Estados | B4: ='AD ESFERA'!D16/100 -> 0.26697113 | C4: ='RD ESFERA'!D11/100 -> 0.25180411 | F4: ='AD ESFERA'!C16 -> 9.5976102 | G4: ='RD ESFERA'!C11 -> 9.052356
A5: Municípios | B5: ='AD ESFERA'!D21/100 -> 0.08521501 | C5: ='RD ESFERA'!D13/100 -> 0.23269174 | F5: ='AD ESFERA'!C21 -> 3.0634789 | G5: ='RD ESFERA'!C13 -> 8.3652662
